Workbook

Sheet 分散分析
A1: 分散分析: 繰り返しのない二元配置
A3: 概要 | B3: 標本数 | C3: 合計 | D3: 平均 | E3: 分散
A4: 100 | B4: 5 | C4: 4.2569251 | D4: 0.85138503 | E4: 0.0083481248
A5: 150 | B5: 5 | C5: 4.2369766 | D5: 0.84739532 | E5: 0.0083107032
A6: 200 | B6: 5 | C6: 4.2748739 | D6: 0.85497477 | E6: 0.0092860567
A7: 250 | B7: 5 | C7: 4.1700201 | D7: 0.83400401 | E7: 0.0095568111
A8: 300 | B8: 5 | C8: 4.2569251 | D8: 0.85138503 | E8: 0.0083481248
A9: 350 | B9: 5 | C9: 4.2555756 | D9: 0.85111512 | E9: 0.0082828123
A10: 400 | B10: 5 | C10: 4.2319018 | D10: 0.84638036 | E10: 0.0081877514
A11: 450 | B11: 5 | C11: 4.2569251 | D11: 0.85138503 | E11: 0.0083481248
A12: 500 | B12: 5 | C12: 4.2222423 | D12: 0.84444846 | E12: 0.0084310273
A13: 550 | B13: 5 | C13: 4.2719578 | D13: 0.85439156 | E13: 0.0084246682
A14: 600 | B14: 5 | C14: 4.2569251 | D14: 0.85138503 | E14: 0.0083481248
A15: 650 | B15: 5 | C15: 4.2569251 | D15: 0.85138503 | E15: 0.0083481248
... A22: 979 | B22: 5 | C22: 4.2706083 | D22: 0.85412166 | E22: 0.0083613844
A24: Polarityチェックの結果 | B24: 19 | C24: 14.687943 | D24: 0.77304965 | E24: 5.2042907e-32
A25: SVMのみによる分類結果 | B25: 19 | C25: 16.142904 | D25: 0.84962654 | E25: 0.00051096372
A26: PolarityチェックとSVM | B26: 19 | C26: 17.728571 | D26: 0.93308271 | E26: 1.1934598e-06
A27: ユーザの評価を用いたSVM | B27: 19 | C27: 18.030203 | D27: 0.94895806 | E27: 6.3060026e-05
A28: ベースライン | B28: 19 | C28: 14.179104 | D28: 0.74626866 | E28: 1.1709654e-31
A31: 分散分析表 | L31: Polarityチェックの結果 | M31: SVMのみによる分類結果 | N31: PolarityチェックとSVM | O31: ユーザの評価を用いたSVM
A32: 変動要因 | B32: 変動 | C32: 自由度 | D32: 分散 | E32: 観測された分散比 | F32: P-値 | G32: F 境界値 | K32: Polarityチェックの結果
A33: 行 | B33: 0.0021673464 | C33: 18 | D33: 0.00012040814 | E33: 1.0589774 | F33: 0.40965585 | G33: 1.7489261 | K33: SVMのみによる分類結果 | L33: =ABS(D24-D25) -> 0.076576893
A34: 列 | B34: 0.63416161 | C34: 4 | D34: 0.1585404 | E34: 1394.3469 | F34: 2.2630967e-67 | G34: 2.4989186 | K34: PolarityチェックとSVM | L34: =ABS(D24-D26) -> 0.16003306 | M34: =ABS(D$25-D26) -> 0.083456168
A35: 誤差 | B35: 0.0081865632 | C35: 72 | D35: 0.00011370227 | K35: ユーザの評価を用いたSVM | L35: =ABS(D24-D27) -> 0.17590841 | M35: =ABS(D$25-D27) -> 0.099331519 | N35: =ABS(D$26-D27) -> 0.01587535
K36: ベースライン | L36: =ABS(D24-D28) -> 0.026780989 | M36: =ABS(D$25-D28) -> 0.10335788 | N36: =ABS(D$26-D28) -> 0.18681405 | O36: =ABS(D$27-D28) -> 0.2026894
A37: 合計 | B37: 0.64451552 | C37: 94
K39: Q(5%) Q(a,(a-1)(b-1)) = (5,4*18) | L39: 3.9774 | M39: 検定統計量→ | N39: =L39*SQRT(D35/18) -> 0.009996491
K40: Q(1%) | L40: 4.8178 | M40: 検定統計量→ | N40: =L40*SQRT(D35/18) -> 0.012108688

Sheet 分散分析3
A1: 分散分析: 繰り返しのない二元配置
A3: 概要 | B3: 標本数 | C3: 合計 | D3: 平均 | E3: 分散
A4: 50 | B4: 5 | C4: 2.9262481 | D4: 0.58524962 | E4: 0.00091507412
A5: 100 | B5: 5 | C5: 3.0208326 | D5: 0.60416652 | E5: 0.0021995656
A6: 150 | B6: 5 | C6: 3.0024041 | D6: 0.60048081 | E6: 0.0021512657
A7: 200 | B7: 5 | C7: 2.9978147 | D7: 0.59956294 | E7: 0.0024888821
A8: 250 | B8: 5 | C8: 2.9586104 | D8: 0.59172207 | E8: 0.0024121536
A9: 300 | B9: 5 | C9: 3.0208326 | D9: 0.60416652 | E9: 0.0021995656
A10: 350 | B10: 5 | C10: 3.0287511 | D10: 0.60575023 | E10: 0.0021490302
A11: 400 | B11: 5 | C11: 2.9865656 | D11: 0.59731311 | E11: 0.0014714591
A12: 450 | B12: 5 | C12: 3.0325973 | D12: 0.60651946 | E12: 0.0021335342
A13: 500 | B13: 5 | C13: 2.9986104 | D13: 0.59972207 | E13: 0.0020977121
A14: 550 | B14: 5 | C14: 3.041823 | D14: 0.60836461 | E14: 0.0022908652
A15: 600 | B15: 5 | C15: 3.0208326 | D15: 0.60416652 | E15: 0.0021995656
... A23: 979 | B23: 5 | C23: 3.0339045 | D23: 0.6067809 | E23: 0.0023517517
A25: Polarityチェックの結果 | B25: 20 | C25: 12.104019 | D25: 0.60520095 | E25: 5.1898744e-32
A26: SVMのみによる分類結果 | B26: 20 | C26: 12.36412 | D26: 0.61820602 | E26: 0.00026164437
A27: PolarityチェックとSVM | B27: 20 | C27: 13.214286 | D27: 0.66071429 | E27: 0.00046992481
A28: ユーザの評価を用いたSVM | B28: 20 | C28: 11.782575 | D28: 0.58912875 | E28: 0.00019544208
A29: ベースライン | B29: 20 | C29: 10.770149 | D29: 0.53850746 | E29: 1.2974686e-32
L31: Polarityチェックの結果 | M31: SVMのみによる分類結果 | N31: PolarityチェックとSVM | O31: ユーザの評価を用いたSVM
A32: 分散分析表 | K32: Polarityチェックの結果
A33: 変動要因 | B33: 変動 | C33: 自由度 | D33: 分散 | E33: 観測された分散比 | F33: P-値 | G33: F 境界値 | K33: SVMのみによる分類結果 | L33: =ABS(D24-D25) -> 0.60520095
A34: 行 | B34: 0.0034929834 | C34: 19 | D34: 0.00018384123 | E34: 0.98949754 | F34: 0.48246851 | G34: 1.7250291 | K34: PolarityチェックとSVM | L34: =ABS(D24-D26) -> 0.61820602 | M34: =ABS(D$25-D26) -> 0.013005079
A35: 列 | B35: 0.15833204 | C35: 4 | D35: 0.039583011 | E35: 213.04955 | F35: 1.8010482e-40 | G35: 2.4920493 | K35: ユーザの評価を用いたSVM | L35: =ABS(D24-D27) -> 0.66071429 | M35: =ABS(D$25-D27) -> 0.05551334 | N35: =ABS(D$26-D27) -> 0.042508261
A36: 誤差 | B36: 0.014120231 | C36: 76 | D36: 0.00018579251 | K36: ベースライン | L36: =ABS(D24-D28) -> 0.58912875 | M36: =ABS(D$25-D28) -> 0.016072191 | N36: =ABS(D$26-D28) -> 0.02907727 | O36: =ABS(D$27-D28) -> 0.071585531
A38: 合計 | B38: 0.17594526 | C38: 99
K39: Q(5%) Q(a,(a-1)(b-1)) = (5,4*18) | L39: 3.9774 | M39: 検定統計量→ | N39: =L39*SQRT(D36/18) -> 0.012778419
K40: Q(1%) | L40: 4.8178 | M40: 検定統計量→ | N40: =L40*SQRT(D36/18) -> 0.01547842

Sheet グラフ
B3: Criteria = 3 | C3: スクリーニング数 | D3: Polarityチェックの結果 | E3: SVMのみによる分類結果 | F3: PolarityチェックとSVM | G3: ユーザの評価を用いたSVM | H3: ベースライン
B4: 適合率 | C4: 100 | D4: ='100'!N7 -> 0.77304965 | E4: ='100'!O7 -> 0.85555556 | F4: ='100'!P7 -> 0.93333333 | G4: ='100'!Q7 -> 0.94871795 | H4: =1250/1675 -> 0.74626866
C5: 150 | D5: ='150'!N7 -> 0.77304965 | E5: ='150'!O7 -> 0.83695652 | F5: ='150'!P7 -> 0.93333333 | G5: ='150'!Q7 -> 0.94736842 | H5: =1250/1675 -> 0.74626866
C6: 200 | D6: ='200'!N7 -> 0.77304965 | E6: ='200'!O7 -> 0.85555556 | F6: ='200'!P7 -> 0.93333333 | G6: ='200'!Q7 -> 0.96666667 | H6: =1250/1675 -> 0.74626866
C7: 250 | D7: ='250'!N7 -> 0.77304965 | E7: ='250'!O7 -> 0.77 | F7: ='250'!P7 -> 0.93333333 | G7: ='250'!Q7 -> 0.94736842 | H7: =1250/1675 -> 0.74626866
C8: 300 | D8: ='300'!N7 -> 0.77304965 | E8: ='300'!O7 -> 0.85555556 | F8: ='300'!P7 -> 0.93333333 | G8: ='300'!Q7 -> 0.94871795 | H8: =1250/1675 -> 0.74626866 | W8: 適合率
C9: 350 | D9: ='350'!N7 -> 0.77304965 | E9: ='350'!O7 -> 0.85555556 | F9: ='350'!P7 -> 0.93333333 | G9: ='350'!Q7 -> 0.94736842 | H9: =1250/1675 -> 0.74626866 | W9: SVM+fasttextの平均 | X9: =AVERAGE(F27:F46) -> 0.66071429 | Z9: =AVERAGE(X9,[1]グラフ!U5,[2]グラフ!W4,[3]グラフ!Y4,[4]グラフ!W4) -> 0.50577052
C10: 400 | D10: ='400'!N7 -> 0.77304965 | E10: ='400'!O7 -> 0.83529412 | F10: ='400'!P7 -> 0.92857143 | G10: ='400'!Q7 -> 0.94871795 | H10: =1250/1675 -> 0.74626866 | W10: SVM+辞書の平均 | X10: =AVERAGE(E27:E46) -> 0.61820602 | Z10: =AVERAGE(X10,[1]グラフ!U6,[2]グラフ!W5,[3]グラフ!Y5,[4]グラフ!W5) -> 0.43167782
C11: 450 | D11: ='450'!N7 -> 0.77304965 | E11: ='450'!O7 -> 0.85555556 | F11: ='450'!P7 -> 0.93333333 | G11: ='450'!Q7 -> 0.94871795 | H11: =1250/1675 -> 0.74626866 | W11: ユーザ評価の平均 | X11: =AVERAGE(G27:G46) -> 0.58912875 | Z11: =AVERAGE(X11,[1]グラフ!U7,[2]グラフ!W6,[3]グラフ!Y6,[4]グラフ!W6) -> 0.50549598
C12: 500 | D12: ='500'!N7 -> 0.77304965 | E12: ='500'!O7 -> 0.82222222 | F12: ='500'!P7 -> 0.93333333 | G12: ='500'!Q7 -> 0.94736842 | H12: =1250/1675 -> 0.74626866 | W12: ランダムの平均 | X12: =AVERAGE(D27:D46) -> 0.60520095 | Z12: =AVERAGE(X12,[1]グラフ!U8,[2]グラフ!W7,[3]グラフ!Y7,[4]グラフ!W7) -> 0.50724416
C13: 550 | D13: ='550'!N7 -> 0.77304965 | E13: ='550'!O7 -> 0.87058824 | F13: ='550'!P7 -> 0.93333333 | G13: ='550'!Q7 -> 0.94871795 | H13: =1250/1675 -> 0.74626866
C14: 600 | D14: ='600'!N7 -> 0.77304965 | E14: ='600'!O7 -> 0.85555556 | F14: ='600'!P7 -> 0.93333333 | G14: ='600'!Q7 -> 0.94871795 | H14: =1250/1675 -> 0.74626866 | W14: F値
C15: 650 | D15: ='650'!N7 -> 0.77304965 | E15: ='650'!O7 -> 0.85555556 | F15: ='650'!P7 -> 0.93333333 | G15: ='650'!Q7 -> 0.94871795 | H15: =1250/1675 -> 0.74626866 | W15: SVM+fasttextの平均 | X15: =AVERAGE(F52:F71) -> 0.021506311 | Z15: =AVERAGE(X15,[1]グラフ!U11,[2]グラフ!W10,[3]グラフ!Y10,[4]グラフ!W10) -> 0.022072487
C16: 700 | D16: ='700'!N7 -> 0.77304965 | E16: ='700'!O7 -> 0.85555556 | F16: ='700'!P7 -> 0.93333333 | G16: ='700'!Q7 -> 0.94736842 | H16: =1250/1675 -> 0.74626866 | W16: SVM+辞書の平均 | X16: =AVERAGE(E52:E71) -> 0.11051044 | Z16: =AVERAGE(X16,[1]グラフ!U12,[2]グラフ!W11,[3]グラフ!Y11,[4]グラフ!W11) -> 0.056736996
C17: 750 | D17: ='750'!N7 -> 0.77304965 | E17: ='750'!O7 -> 0.85555556 | F17: ='750'!P7 -> 0.93333333 | G17: ='750'!Q7 -> 0.94871795 | H17: =1250/1675 -> 0.74626866 | W17: ユーザ評価の平均 | X17: =AVERAGE(G52:G71) -> 0.055744344 | Z17: =AVERAGE(X17,[1]グラフ!U13,[2]グラフ!W12,[3]グラフ!Y12,[4]グラフ!W12) -> 0.50239676
C18: 800 | D18: ='800'!N7 -> 0.77304965 | E18: ='800'!O7 -> 0.87058824 | F18: ='800'!P7 -> 0.93333333 | G18: ='800'!Q7 -> 0.94736842 | H18: =1250/1675 -> 0.74626866 | W18: ランダムの平均 | X18: =AVERAGE(D52:D71) -> 0.39091452 | Z18: =AVERAGE(X18,[1]グラフ!U14,[2]グラフ!W13,[3]グラフ!Y13,[4]グラフ!W13) -> 0.37393282
C19: 850 | D19: ='850'!N7 -> 0.77304965 | E19: ='850'!O7 -> 0.85555556 | F19: ='850'!P7 -> 0.93333333 | G19: ='850'!Q7 -> 0.96666667 | H19: =1250/1675 -> 0.74626866
C20: 900 | D20: ='900'!N7 -> 0.77304965 | E20: ='900'!O7 -> 0.85555556 | F20: ='900'!P7 -> 0.93333333 | G20: ='900'!Q7 -> 0.94871795 | H20: =1250/1675 -> 0.74626866 | W20: 再現率
C21: 950 | D21: ='950'!N7 -> 0.77304965 | E21: ='950'!O7 -> 0.85555556 | F21: ='950'!P7 -> 0.93333333 | G21: ='950'!Q7 -> 0.92682927 | H21: =1250/1675 -> 0.74626866 | W21: SVM+fasttextの平均 | X21: =(X9*X15)/(2*X9-X15) -> 0.010931059 | Z21: =AVERAGE(X21,[1]グラフ!U17,[2]グラフ!W16,[3]グラフ!Y16,[4]グラフ!W16) -> 0.011296402
C22: 979 | D22: ='979'!N7 -> 0.77304965 | E22: ='979'!O7 -> 0.87058824 | F22: ='979'!P7 -> 0.93333333 | G22: ='979'!Q7 -> 0.94736842 | H22: =1250/1675 -> 0.74626866 | W22: SVM+辞書の平均 | X22: =(X10*X16)/(2*X10-X16) -> 0.060678679 | Z22: =AVERAGE(X22,[1]グラフ!U18,[2]グラフ!W17,[3]グラフ!Y17,[4]グラフ!W17) -> 0.030816628
W23: ユーザ評価の平均 | X23: =(X11*X17)/(2*X11-X17) -> 0.029256313 | Z23: =AVERAGE(X23,[1]グラフ!U19,[2]グラフ!W18,[3]グラフ!Y18,[4]グラフ!W18) -> 0.70671463
W24: fastTextのみの平均 | X24: =(X12*X18)/(2*X12-X18) -> 0.28869492 | Z24: =AVERAGE(X24,[1]グラフ!U20,[2]グラフ!W19,[3]グラフ!Y19,[4]グラフ!W19) -> 0.29873198
B26: Criteria = 4 | C26: スクリーニング数 | D26: Polarityチェックの結果 | E26: SVMのみによる分類結果 | F26: PolarityチェックとSVM | G26: ユーザの評価を用いたSVM | H26: ベースライン
B27: 適合率 | C27: 50 | D27: ='50'!N16 -> 0.60520095 | E27: ='50'!O16 -> 0.61111111 | F27: ='50'!P16 -> 0.57142857 | G27: ='50'!Q16 -> 0.6 | H27: =902/1675 -> 0.53850746
C28: 100 | D28: ='100'!N16 -> 0.60520095 | E28: ='100'!O16 -> 0.62222222 | F28: ='100'!P16 -> 0.66666667 | G28: ='100'!Q16 -> 0.58823529 | H28: =902/1675 -> 0.53850746
C29: 150 | D29: ='150'!N16 -> 0.60520095 | E29: ='150'!O16 -> 0.60869565 | F29: ='150'!P16 -> 0.66666667 | G29: ='150'!Q16 -> 0.58333333 | H29: =902/1675 -> 0.53850746
C30: 200 | D30: ='200'!N16 -> 0.60520095 | E30: ='200'!O16 -> 0.62222222 | F30: ='200'!P16 -> 0.66666667 | G30: ='200'!Q16 -> 0.56521739 | H30: =902/1675 -> 0.53850746
C31: 250 | D31: ='250'!N16 -> 0.60520095 | E31: ='250'!O16 -> 0.56 | F31: ='250'!P16 -> 0.66666667 | G31: ='250'!Q16 -> 0.58823529 | H31: =902/1675 -> 0.53850746
C32: 300 | D32: ='300'!N16 -> 0.60520095 | E32: ='300'!O16 -> 0.62222222 | F32: ='300'!P16 -> 0.66666667 | G32: ='300'!Q16 -> 0.58823529 | H32: =902/1675 -> 0.53850746
C33: 350 | D33: ='350'!N16 -> 0.60520095 | E33: ='350'!O16 -> 0.62222222 | F33: ='350'!P16 -> 0.66666667 | G33: ='350'!Q16 -> 0.59615385 | H33: =902/1675 -> 0.53850746
C34: 400 | D34: ='400'!N16 -> 0.60520095 | E34: ='400'!O16 -> 0.61176471 | F34: ='400'!P16 -> 0.64285714 | G34: ='400'!Q16 -> 0.58823529 | H34: =902/1675 -> 0.53850746
C35: 450 | D35: ='450'!N16 -> 0.60520095 | E35: ='450'!O16 -> 0.62222222 | F35: ='450'!P16 -> 0.66666667 | G35: ='450'!Q16 -> 0.6 | H35: =902/1675 -> 0.53850746
C36: 500 | D36: ='500'!N16 -> 0.60520095 | E36: ='500'!O16 -> 0.6 | F36: ='500'!P16 -> 0.66666667 | G36: ='500'!Q16 -> 0.58823529 | H36: =902/1675 -> 0.53850746
C37: 550 | D37: ='550'!N16 -> 0.60520095 | E37: ='550'!O16 -> 0.63529412 | F37: ='550'!P16 -> 0.66666667 | G37: ='550'!Q16 -> 0.59615385 | H37: =902/1675 -> 0.53850746 | J37: FastText
C38: 600 | D38: ='600'!N16 -> 0.60520095 | E38: ='600'!O16 -> 0.62222222 | F38: ='600'!P16 -> 0.66666667 | G38: ='600'!Q16 -> 0.58823529 | H38: =902/1675 -> 0.53850746 | J38: SVM+FastText(提案1)
C39: 650 | D39: ='650'!N16 -> 0.60520095 | E39: ='650'!O16 -> 0.62222222 | F39: ='650'!P16 -> 0.66666667 | G39: ='650'!Q16 -> 0.58 | H39: =902/1675 -> 0.53850746 | J39: SVM+極性辞書(提案2)
C40: 700 | D40: ='700'!N16 -> 0.60520095 | E40: ='700'!O16 -> 0.62222222 | F40: ='700'!P16 -> 0.66666667 | G40: ='700'!Q16 -> 0.58823529 | H40: =902/1675 -> 0.53850746 | J40: ユーザの評価を用いたSVM
C41: 750 | D41: ='750'!N16 -> 0.60520095 | E41: ='750'!O16 -> 0.62222222 | F41: ='750'!P16 -> 0.66666667 | G41: ='750'!Q16 -> 0.63414634 | H41: =902/1675 -> 0.53850746 | J41: ベースライン
C42: 800 | D42: ='800'!N16 -> 0.60520095 | E42: ='800'!O16 -> 0.63529412 | F42: ='800'!P16 -> 0.66666667 | G42: ='800'!Q16 -> 0.58823529 | H42: =902/1675 -> 0.53850746
C43: 850 | D43: ='850'!N16 -> 0.60520095 | E43: ='850'!O16 -> 0.62222222 | F43: ='850'!P16 -> 0.66666667 | G43: ='850'!Q16 -> 0.58 | H43: =902/1675 -> 0.53850746
...

Sheet 相関係数
B1: 映画を肯定的に評価している | C1: 映画を推薦しているレビューである
A2: 映画を肯定的に評価している | B2: 1
A3: 映画を推薦しているレビューである | B3: 0.73274621 | C3: 1
B6: 映画を推薦しているレビューである | C6: 映画の特徴を表している
A7: 映画を推薦しているレビューである | B7: 1
A8: 映画の特徴を表している | B8: 0.51165709 | C8: 1
A13: サンプル数(N) | B13: 1674
A16: 肯定的な評価の相関係数における無相関を帰無仮説とした場合の有意差導出
B17: 値
A18: 相関係数r | B18: =B3 -> 0.73274621
A19: t | B19: =ABS(B18)*SQRT(B13-2)/SQRT(1-B18^2) -> 44.029353
A20: p値 | B20: =TDIST(B19,B13-2,2) -> 8.2386564e-282
A23: 映画の特徴の相関係数における無相関を帰無仮説とした場合の有意差導出
B24: 値
A25: 相関係数r | B25: =B8 -> 0.51165709
A26: t | B26: =ABS(B25)*SQRT(B13-2)/SQRT(1-B25^2) -> 24.350509
A27: p値 | B27: =TDIST(B26,B13-2,2) -> 2.3850722e-112

Sheet 相関調査用
D1: 映画を肯定的に評価している | E1: 映画を推薦しているレビューである | F1: 映画の特徴を表している
D2: 2 | E2: 2 | F2: 1
D3: 5 | E3: 5 | F3: 5
D4: 2 | E4: 2 | F4: 5
D5: 5 | E5: 4 | F5: 2
D6: 4 | E6: 3 | F6: 5
D7: 5 | E7: 1 | F7: 1
D8: 4 | E8: 2 | F8: 1
D9: 5 | E9: 1 | F9: 1
D10: 5 | E10: 3 | F10: 3
D11: 4 | E11: 3 | F11: 4
D12: 5 | E12: 4 | F12: 4
D13: 2 | E13: 2 | F13: 3
... D1675: 5 | E1675: 5 | F1675: 4

Sheet 50
A1: レビュー文 | B1: 映画を肯定的に評価している | C1: 映画の特徴を表している | D1: 映画を推薦しているレビューである | E1: 映画を見たいと思えるレビューである | F1: Polarityチェックの結果 | G1: SVMによる分類結果 | H1: PolarityチェックとSVMの組み合わせ | I1: ユーザのレビューに対する評価を用いたSVMの場合.criteria = 3 | J1: ユーザのレビューに対する評価を用いたSVMの場合.criteria = 4
A2: 日本人だったら、あれ程には勉強せぬまま作品化してしまうのではないか、という想いが湧きました | B2: 2 | C2: 1 | D2: 2 | E2: 1 | F2: 1 | G2: -10 | H2: -1 | I2: -10 | J2: -10
A3: テンポの良さ、キャラクターの個性、観客を最後まで楽しませようというエンターテイメント魂に感服いたします | B3: 5 | C3: 5 | D3: 5 | E3: 4 | F3: -1 | G3: -10 | H3: -1 | I3: -10 | J3: -10 | L3: Criteria = 3
A4: 特撮を含めて映像センスは素晴らしいが監督自身がそれに酔っているようで『この映画凄いでしょう』と言っているみたいに感じる | B4: 2 | C4: 5 | D4: 2 | E4: 3 | F4: -1 | G4: -10 | H4: -1 | I4: -10 | J4: -10 | M4: 推薦文として認識された文 | N4: Polarityチェックの結果 | O4: SVMによる分類結果 | P4: PolarityチェックとSVM | Q4: ユーザの評価を用いたSVM
A5: ＤＶＤを買って結構頻繁に観てるけどその度にわくわくと楽しい気分にさせてくれる映画 | B5: 5 | C5: 2 | D5: 4 | E5: 5 | F5: -1 | G5: -10 | H5: -1 | I5: -10 | J5: -10 | L5: 総数 | M5: =COUNTIF(D2:D4000,">=3") -> 1250 | N5: =COUNTIF(F2:F4000,">=1") -> 423 | O5: =COUNTIF(G2:G4000,">=0") -> 36 | P5: =COUNTIFS(H2:H4000,">=0") -> 7 | Q5: =COUNTIF(I2:I4000,">=0") -> 39
A6: やっぱ、ラプターが天井目掛けて飛びあがるシーンと、T-REXがジープを追いかけてそれがミラーに映るシーンが一番印象深いです | B6: 4 | C6: 5 | D6: 3 | E6: 5 | F6: 1 | G6: -10 | H6: -1 | I6: -10 | J6: -10 | L6: 一致数 | N6: =COUNTIFS(D2:D4000,">=3",F2:F4000,">=1") -> 327 | O6: =COUNTIFS(D2:D4000,">=3",G2:G4000,">=1") -> 34 | P6: =COUNTIFS(D2:D4000,">=3",H2:H4000,">=1") -> 7 | Q6: =COUNTIFS(D2:D4000,">=3",I2:I4000,">=0") -> 37
A7: コレは名作じゃ | B7: 5 | C7: 1 | D7: 1 | E7: 2 | F7: -1 | G7: -10 | H7: -1 | I7: -10 | J7: -10 | L7: 適合率 | N7: =N6/N5 -> 0.77304965 | O7: =O6/O5 -> 0.94444444 | P7: =P6/P5 -> 1 | Q7: =Q6/Q5 -> 0.94871795
A8: 内容にも破鎖がなく、安心して見られました | B8: 4 | C8: 1 | D8: 2 | E8: 2 | F8: -1 | G8: -10 | H8: -1 | I8: -10 | J8: -10 | L8: 再現率 | N8: =N6/M5 -> 0.2616 | O8: =O6/M5 -> 0.0272 | P8: =P6/M5 -> 0.0056 | Q8: =Q6/M5 -> 0.0296
A9: 曲が美しい | B9: 5 | C9: 1 | D9: 1 | E9: 2 | F9: -1 | G9: -10 | H9: -1 | I9: -10 | J9: -10 | L9: F値 | N9: =(2*N7*N8)/(N7+N8) -> 0.39091452 | O9: =(2*O7*O8)/(O7+O8) -> 0.052877138 | P9: =(2*P7*P8)/(P7+P8) -> 0.011137629 | Q9: =(2*Q7*Q8)/(Q7+Q8) -> 0.057408844
A10: 子役の演技がいいね | B10: 5 | C10: 3 | D10: 3 | E10: 4 | F10: -1 | G10: -10 | H10: -1 | I10: -10 | J10: -10
A11: 誰も見たこともない古代の映像を実にリアル | B11: 4 | C11: 4 | D11: 3 | E11: 4 | F11: -1 | G11: -10 | H11: -1 | I11: -10 | J11: -10
A12: でも迫力あってよかったです | B12: 5 | C12: 4 | D12: 4 | E12: 4 | F12: -1 | G12: -10 | H12: -1 | I12: -10 | J12: -10 | L12: Criteria = 4
A13: 恐竜好きの僕にはラプターも良いけどアロサウルスを出して欲しかった | B13: 2 | C13: 3 | D13: 2 | E13: 2 | F13: -1 | G13: 10 | H13: -1 | I13: -10 | J13: -10 | M13: 推薦文として認識された文 | N13: Polarityチェックの結果 | O13: SVMによる分類結果 | P13: PolarityチェックとSVM | Q13: ユーザの評価を用いたSVM
A14: テンポも速いしいいと思う | B14: 3 | C14: 4 | D14: 2 | E14: 4 | F14: -1 | G14: -10 | H14: -1 | I14: -10 | J14: -10 | L14: 総数 | M14: =COUNTIF(D2:D4000,">=4") -> 902 | N14: =COUNTIF(F2:F4000,">=1") -> 423 | O14: =COUNTIF(G2:G4000,">=0") -> 36 | P14: =COUNTIFS(H2:H4000,">=1") -> 7 | Q14: =COUNTIF(J2:J4000,">=0") -> 50
A15: ）はスピルバーグのシナリオ力量の無さの証拠 | B15: 1 | C15: 2 | D15: 1 | E15: 1 | F15: -1 | G15: -10 | H15: -1 | I15: -10 | J15: -10 | L15: 一致数 | N15: =COUNTIFS(D2:D4000,">=4",F2:F4000,">=1") -> 256 | O15: =COUNTIFS(D2:D4000,">=4",G2:G4000,">=1") -> 22 | P15: =COUNTIFS(D2:D4000,">=4",H2:H4000,">=1") -> 4 | Q15: =COUNTIFS(D2:D4000,">=4",J2:J4000,">=0") -> 30
A16: 役者陣も個性豊かな芸達者でさすがという所 | B16: 5 | C16: 4 | D16: 4 | E16: 5 | F16: -1 | G16: -10 | H16: -1 | I16: -10 | J16: -10 | L16: 適合率 | N16: =N15/N14 -> 0.60520095 | O16: =O15/O14 -> 0.61111111 | P16: =P15/P14 -> 0.57142857 | Q16: =Q15/Q14 -> 0.6
A17: 超優良なアドベンチャー映画に7点献上 | B17: 5 | C17: 4 | D17: 5 | E17: 5 | F17: -1 | G17: -10 | H17: -1 | I17: -10 | J17: -10 | L17: 再現率 | N17: =N15/M14 -> 0.28381375 | O17: =O15/M14 -> 0.024390244 | P17: =P15/M14 -> 0.0044345898 | Q17: =Q15/M14 -> 0.033259424
A18: 配役も好き | B18: 4 | C18: 1 | D18: 1 | E18: 3 | F18: -1 | G18: -10 | H18: -1 | I18: -10 | J18: -10 | L18: F値 | N18: =(2*N16*N17)/(N16+N17) -> 0.38641509 | O18: =(2*O16*O17)/(O16+O17) -> 0.046908316 | P18: =(2*P16*P17)/(P16+P17) -> 0.0088008801 | Q18: =(2*Q16*Q17)/(Q16+Q17) -> 0.06302521
A19: 」と、お互いの顔を見つめ合ってしまいました | B19: 1 | C19: 1 | D19: 1 | E19: 1 | F19: -1 | G19: -10 | H19: -1 | I19: -10 | J19: -10
A20: ストーリーは確かにちょっとアレでしたが、初めて観た時の感動はかなりのものでした | B20: 4 | C20: 4 | D20: 5 | E20: 5 | F20: 1 | G20: -10 | H20: -1 | I20: -10 | J20: -10
A21: 当時映画館で見たときには度肝を抜かれた（古い表現だぁ）単純な娯楽作品なんだけど、遺伝子操作を行うことへの警鐘にも触れていて多面的に楽しめるお気軽作品 | B21: 5 | C21: 5 | D21: 5 | E21: 5 | F21: -1 | G21: -10 | H21: -1 | I21: -10 | J21: -10
A22: だから大人になった自分は、そんな子供心があった自分を今でも覚えていられるのはそのとき出会った映画のおかげなんですよね | B22: 4 | C22: 3 | D22: 4 | E22: 4 | F22: 1 | G22: -10 | H22: -1 | I22: -10 | J22: -10
A23: こうゆうのを「娯楽作品っ | B23: 1 | C23: 1 | D23: 1 | E23: 1 | F23: -1 | G23: -10 | H23: -1 | I23: -10 | J23: -10
A24: もっともストーリーはハラハラドキドキでちっとも安心できませんけどね | B24: 2 | C24: 4 | D24: 2 | E24: 1 | F24: 1 | G24: -10 | H24: -1 | I24: -10 | J24: -10
A25: 良くまとまった作品だと思います | B25: 4 | C25: 1 | D25: 1 | E25: 2 | F25: -1 | G25: -10 | H25: -1 | I25: -10 | J25: -10
A26: スピルバーグ最高 | B26: 4 | C26: 1 | D26: 2 | E26: 2 | F26: -1 | G26: -10 | H26: -1 | I26: -10 | J26: -10
A27: 観ててあのリアルな感じがストレートに伝わってきた | B27: 5 | C27: 4 | D27: 2 | E27: 3 | F27: -1 | G27: -10 | H27: -1 | I27: -10 | J27: -10
A28: 子供が良かったです | B28: 4 | C28: 1 | D28: 1 | E28: 1 | F28: -1 | G28: -10 | H28: -1 | I28: -10 | J28: -10
A29: というかこれみたら、ああ・・当時はこんなだったのかなあ、と素直に信じれます | B29: 3 | C29: 3 | D29: 3 | E29: 2 | F29: -1 | G29: -10 | H29: -1 | I29: -10 | J29: -10
A30: 満点です | B30: 5 | C30: 1 | D30: 1 | E30: 1 | F30: -1 | G30: -10 | H30: -1 | I30: -10 | J30: -10
... A1675: 映画の世界でそんな難題に挑み、奇跡的に満足できる商品を作ってしまったのが本作 | B1675: 5 | C1675: 4 | D1675: 5 | E1675: 5 | F1675: 1 | G1675: -10 | H1675: -1 | I1675: -10 | J1675: -10

Sheet 100
A1: レビュー文 | B1: 映画を肯定的に評価している | C1: 映画の特徴を表している | D1: 映画を推薦しているレビューである | E1: 映画を見たいと思えるレビューである | F1: Polarityチェックの結果 | G1: SVMによる分類結果 | H1: PolarityチェックとSVMの組み合わせ | I1: ユーザのレビューに対する評価を用いたSVMの場合.criteria = 3 | J1: ユーザのレビューに対する評価を用いたSVMの場合.criteria = 4
A2: 日本人だったら、あれ程には勉強せぬまま作品化してしまうのではないか、という想いが湧きました | B2: 2 | C2: 1 | D2: 2 | E2: 1 | F2: 1 | G2: -10 | H2: -1 | I2: -10 | J2: -10
A3: テンポの良さ、キャラクターの個性、観客を最後まで楽しませようというエンターテイメント魂に感服いたします | B3: 5 | C3: 5 | D3: 5 | E3: 4 | F3: -1 | G3: -10 | H3: -1 | I3: -10 | J3: -10 | L3: Criteria = 3
A4: 特撮を含めて映像センスは素晴らしいが監督自身がそれに酔っているようで『この映画凄いでしょう』と言っているみたいに感じる | B4: 2 | C4: 5 | D4: 2 | E4: 3 | F4: -1 | G4: -10 | H4: -1 | I4: -10 | J4: -10 | M4: 推薦文として認識された文 | N4: Polarityチェックの結果 | O4: SVMによる分類結果 | P4: PolarityチェックとSVM | Q4: ユーザの評価を用いたSVM
A5: ＤＶＤを買って結構頻繁に観てるけどその度にわくわくと楽しい気分にさせてくれる映画 | B5: 5 | C5: 2 | D5: 4 | E5: 5 | F5: -1 | G5: -10 | H5: -1 | I5: -10 | J5: -10 | L5: 総数 | M5: =COUNTIF(D2:D4000,">=3") -> 1250 | N5: =COUNTIF(F2:F4000,">=1") -> 423 | O5: =COUNTIF(G2:G4000,">=0") -> 90 | P5: =COUNTIFS(H2:H4000,">=0") -> 15 | Q5: =COUNTIF(I2:I4000,">=0") -> 39
A6: やっぱ、ラプターが天井目掛けて飛びあがるシーンと、T-REXがジープを追いかけてそれがミラーに映るシーンが一番印象深いです | B6: 4 | C6: 5 | D6: 3 | E6: 5 | F6: 1 | G6: -10 | H6: -1 | I6: -10 | J6: -10 | L6: 一致数 | N6: =COUNTIFS(D2:D4000,">=3",F2:F4000,">=1") -> 327 | O6: =COUNTIFS(D2:D4000,">=3",G2:G4000,">=1") -> 77 | P6: =COUNTIFS(D2:D4000,">=3",H2:H4000,">=1") -> 14 | Q6: =COUNTIFS(D2:D4000,">=3",I2:I4000,">=0") -> 37
A7: コレは名作じゃ | B7: 5 | C7: 1 | D7: 1 | E7: 2 | F7: -1 | G7: -10 | H7: -1 | I7: -10 | J7: -10 | L7: 適合率 | N7: =N6/N5 -> 0.77304965 | O7: =O6/O5 -> 0.85555556 | P7: =P6/P5 -> 0.93333333 | Q7: =Q6/Q5 -> 0.94871795
A8: 内容にも破鎖がなく、安心して見られました | B8: 4 | C8: 1 | D8: 2 | E8: 2 | F8: -1 | G8: -10 | H8: -1 | I8: -10 | J8: -10 | L8: 再現率 | N8: =N6/M5 -> 0.2616 | O8: =O6/M5 -> 0.0616 | P8: =P6/M5 -> 0.0112 | Q8: =Q6/M5 -> 0.0296
A9: 曲が美しい | B9: 5 | C9: 1 | D9: 1 | E9: 2 | F9: -1 | G9: -10 | H9: -1 | I9: -10 | J9: -10 | L9: F値 | N9: =(2*N7*N8)/(N7+N8) -> 0.39091452 | O9: =(2*O7*O8)/(O7+O8) -> 0.11492537 | P9: =(2*P7*P8)/(P7+P8) -> 0.022134387 | Q9: =(2*Q7*Q8)/(Q7+Q8) -> 0.057408844
A10: 子役の演技がいいね | B10: 5 | C10: 3 | D10: 3 | E10: 4 | F10: -1 | G10: -10 | H10: -1 | I10: -10 | J10: -10
A11: 誰も見たこともない古代の映像を実にリアル | B11: 4 | C11: 4 | D11: 3 | E11: 4 | F11: -1 | G11: -10 | H11: -1 | I11: -10 | J11: -10
A12: でも迫力あってよかったです | B12: 5 | C12: 4 | D12: 4 | E12: 4 | F12: -1 | G12: -10 | H12: -1 | I12: -10 | J12: -10 | L12: Criteria = 4
A13: 恐竜好きの僕にはラプターも良いけどアロサウルスを出して欲しかった | B13: 2 | C13: 3 | D13: 2 | E13: 2 | F13: -1 | G13: 10 | H13: -1 | I13: -10 | J13: -10 | M13: 推薦文として認識された文 | N13: Polarityチェックの結果 | O13: SVMによる分類結果 | P13: PolarityチェックとSVM | Q13: ユーザの評価を用いたSVM
A14: テンポも速いしいいと思う | B14: 3 | C14: 4 | D14: 2 | E14: 4 | F14: -1 | G14: -10 | H14: -1 | I14: -10 | J14: -10 | L14: 総数 | M14: =COUNTIF(D2:D4000,">=4") -> 902 | N14: =COUNTIF(F2:F4000,">=1") -> 423 | O14: =COUNTIF(G2:G4000,">=0") -> 90 | P14: =COUNTIFS(H2:H4000,">=1") -> 15 | Q14: =COUNTIF(J2:J4000,">=0") -> 51
A15: ）はスピルバーグのシナリオ力量の無さの証拠 | B15: 1 | C15: 2 | D15: 1 | E15: 1 | F15: -1 | G15: -10 | H15: -1 | I15: -10 | J15: -10 | L15: 一致数 | N15: =COUNTIFS(D2:D4000,">=4",F2:F4000,">=1") -> 256 | O15: =COUNTIFS(D2:D4000,">=4",G2:G4000,">=1") -> 56 | P15: =COUNTIFS(D2:D4000,">=4",H2:H4000,">=1") -> 10 | Q15: =COUNTIFS(D2:D4000,">=4",J2:J4000,">=0") -> 30
A16: 役者陣も個性豊かな芸達者でさすがという所 | B16: 5 | C16: 4 | D16: 4 | E16: 5 | F16: -1 | G16: -10 | H16: -1 | I16: -10 | J16: -10 | L16: 適合率 | N16: =N15/N14 -> 0.60520095 | O16: =O15/O14 -> 0.62222222 | P16: =P15/P14 -> 0.66666667 | Q16: =Q15/Q14 -> 0.58823529
A17: 超優良なアドベンチャー映画に7点献上 | B17: 5 | C17: 4 | D17: 5 | E17: 5 | F17: -1 | G17: -10 | H17: -1 | I17: -10 | J17: -10 | L17: 再現率 | N17: =N15/M14 -> 0.28381375 | O17: =O15/M14 -> 0.062084257 | P17: =P15/M14 -> 0.011086475 | Q17: =Q15/M14 -> 0.033259424
A18: 配役も好き | B18: 4 | C18: 1 | D18: 1 | E18: 3 | F18: -1 | G18: -10 | H18: -1 | I18: -10 | J18: -10 | L18: F値 | N18: =(2*N16*N17)/(N16+N17) -> 0.38641509 | O18: =(2*O16*O17)/(O16+O17) -> 0.11290323 | P18: =(2*P16*P17)/(P16+P17) -> 0.021810251 | Q18: =(2*Q16*Q17)/(Q16+Q17) -> 0.062959077
A19: 」と、お互いの顔を見つめ合ってしまいました | B19: 1 | C19: 1 | D19: 1 | E19: 1 | F19: -1 | G19: -10 | H19: -1 | I19: -10 | J19: -10
A20: ストーリーは確かにちょっとアレでしたが、初めて観た時の感動はかなりのものでした | B20: 4 | C20: 4 | D20: 5 | E20: 5 | F20: 1 | G20: -10 | H20: -1 | I20: -10 | J20: -10
A21: 当時映画館で見たときには度肝を抜かれた（古い表現だぁ）単純な娯楽作品なんだけど、遺伝子操作を行うことへの警鐘にも触れていて多面的に楽しめるお気軽作品 | B21: 5 | C21: 5 | D21: 5 | E21: 5 | F21: -1 | G21: -10 | H21: -1 | I21: -10 | J21: -10
A22: だから大人になった自分は、そんな子供心があった自分を今でも覚えていられるのはそのとき出会った映画のおかげなんですよね | B22: 4 | C22: 3 | D22: 4 | E22: 4 | F22: 1 | G22: -10 | H22: -1 | I22: -10 | J22: -10
A23: こうゆうのを「娯楽作品っ | B23: 1 | C23: 1 | D23: 1 | E23: 1 | F23: -1 | G23: -10 | H23: -1 | I23: -10 | J23: -10
A24: もっともストーリーはハラハラドキドキでちっとも安心できませんけどね | B24: 2 | C24: 4 | D24: 2 | E24: 1 | F24: 1 | G24: -10 | H24: -1 | I24: -10 | J24: -10
A25: 良くまとまった作品だと思います | B25: 4 | C25: 1 | D25: 1 | E25: 2 | F25: -1 | G25: -10 | H25: -1 | I25: -10 | J25: -10
A26: スピルバーグ最高 | B26: 4 | C26: 1 | D26: 2 | E26: 2 | F26: -1 | G26: -10 | H26: -1 | I26: -10 | J26: -10
A27: 観ててあのリアルな感じがストレートに伝わってきた | B27: 5 | C27: 4 | D27: 2 | E27: 3 | F27: -1 | G27: -10 | H27: -1 | I27: -10 | J27: -10
A28: 子供が良かったです | B28: 4 | C28: 1 | D28: 1 | E28: 1 | F28: -1 | G28: -10 | H28: -1 | I28: -10 | J28: -10
A29: というかこれみたら、ああ・・当時はこんなだったのかなあ、と素直に信じれます | B29: 3 | C29: 3 | D29: 3 | E29: 2 | F29: -1 | G29: -10 | H29: -1 | I29: -10 | J29: -10
A30: 満点です | B30: 5 | C30: 1 | D30: 1 | E30: 1 | F30: -1 | G30: -10 | H30: -1 | I30: -10 | J30: -10
... A1675: 映画の世界でそんな難題に挑み、奇跡的に満足できる商品を作ってしまったのが本作 | B1675: 5 | C1675: 4 | D1675: 5 | E1675: 5 | F1675: 1 | G1675: -10 | H1675: -1 | I1675: -10 | J1675: -10

Sheet 150
A1: レビュー文 | B1: 映画を肯定的に評価している | C1: 映画の特徴を表している | D1: 映画を推薦しているレビューである | E1: 映画を見たいと思えるレビューである | F1: Polarityチェックの結果 | G1: SVMによる分類結果 | H1: PolarityチェックとSVMの組み合わせ | I1: ユーザのレビューに対する評価を用いたSVMの場合.criteria = 3 | J1: ユーザのレビューに対する評価を用いたSVMの場合.criteria = 4
A2: 日本人だったら、あれ程には勉強せぬまま作品化してしまうのではないか、という想いが湧きました | B2: 2 | C2: 1 | D2: 2 | E2: 1 | F2: 1 | G2: -10 | H2: -1 | I2: -10 | J2: -10
A3: テンポの良さ、キャラクターの個性、観客を最後まで楽しませようというエンターテイメント魂に感服いたします | B3: 5 | C3: 5 | D3: 5 | E3: 4 | F3: -1 | G3: -10 | H3: -1 | I3: -10 | J3: -10 | L3: Criteria = 3
A4: 特撮を含めて映像センスは素晴らしいが監督自身がそれに酔っているようで『この映画凄いでしょう』と言っているみたいに感じる | B4: 2 | C4: 5 | D4: 2 | E4: 3 | F4: -1 | G4: -10 | H4: -1 | I4: -10 | J4: -10 | M4: 推薦文として認識された文 | N4: Polarityチェックの結果 | O4: SVMによる分類結果 | P4: PolarityチェックとSVM | Q4: ユーザの評価を用いたSVM
A5: ＤＶＤを買って結構頻繁に観てるけどその度にわくわくと楽しい気分にさせてくれる映画 | B5: 5 | C5: 2 | D5: 4 | E5: 5 | F5: -1 | G5: -10 | H5: -1 | I5: -10 | J5: -10 | L5: 総数 | M5: =COUNTIF(D2:D4000,">=3") -> 1250 | N5: =COUNTIF(F2:F4000,">=1") -> 423 | O5: =COUNTIF(G2:G4000,">=0") -> 92 | P5: =COUNTIFS(H2:H4000,">=0") -> 15 | Q5: =COUNTIF(I2:I4000,">=0") -> 38
A6: やっぱ、ラプターが天井目掛けて飛びあがるシーンと、T-REXがジープを追いかけてそれがミラーに映るシーンが一番印象深いです | B6: 4 | C6: 5 | D6: 3 | E6: 5 | F6: 1 | G6: -10 | H6: -1 | I6: -10 | J6: -10 | L6: 一致数 | N6: =COUNTIFS(D2:D4000,">=3",F2:F4000,">=1") -> 327 | O6: =COUNTIFS(D2:D4000,">=3",G2:G4000,">=1") -> 77 | P6: =COUNTIFS(D2:D4000,">=3",H2:H4000,">=1") -> 14 | Q6: =COUNTIFS(D2:D4000,">=3",I2:I4000,">=0") -> 36
A7: コレは名作じゃ | B7: 5 | C7: 1 | D7: 1 | E7: 2 | F7: -1 | G7: -10 | H7: -1 | I7: -10 | J7: -10 | L7: 適合率 | N7: =N6/N5 -> 0.77304965 | O7: =O6/O5 -> 0.83695652 | P7: =P6/P5 -> 0.93333333 | Q7: =Q6/Q5 -> 0.94736842
A8: 内容にも破鎖がなく、安心して見られました | B8: 4 | C8: 1 | D8: 2 | E8: 2 | F8: -1 | G8: -10 | H8: -1 | I8: -10 | J8: -10 | L8: 再現率 | N8: =N6/M5 -> 0.2616 | O8: =O6/M5 -> 0.0616 | P8: =P6/M5 -> 0.0112 | Q8: =Q6/M5 -> 0.0288
A9: 曲が美しい | B9: 5 | C9: 1 | D9: 1 | E9: 2 | F9: -1 | G9: -10 | H9: -1 | I9: -10 | J9: -10 | L9: F値 | N9: =(2*N7*N8)/(N7+N8) -> 0.39091452 | O9: =(2*O7*O8)/(O7+O8) -> 0.1147541 | P9: =(2*P7*P8)/(P7+P8) -> 0.022134387 | Q9: =(2*Q7*Q8)/(Q7+Q8) -> 0.055900621
A10: 子役の演技がいいね | B10: 5 | C10: 3 | D10: 3 | E10: 4 | F10: -1 | G10: -10 | H10: -1 | I10: -10 | J10: -10
A11: 誰も見たこともない古代の映像を実にリアル | B11: 4 | C11: 4 | D11: 3 | E11: 4 | F11: -1 | G11: -10 | H11: -1 | I11: -10 | J11: -10
A12: でも迫力あってよかったです | B12: 5 | C12: 4 | D12: 4 | E12: 4 | F12: -1 | G12: -10 | H12: -1 | I12: -10 | J12: -10 | L12: Criteria = 4
A13: 恐竜好きの僕にはラプターも良いけどアロサウルスを出して欲しかった | B13: 2 | C13: 3 | D13: 2 | E13: 2 | F13: -1 | G13: 10 | H13: -1 | I13: -10 | J13: -10 | M13: 推薦文として認識された文 | N13: Polarityチェックの結果 | O13: SVMによる分類結果 | P13: PolarityチェックとSVM | Q13: ユーザの評価を用いたSVM
A14: テンポも速いしいいと思う | B14: 3 | C14: 4 | D14: 2 | E14: 4 | F14: -1 | G14: -10 | H14: -1 | I14: -10 | J14: -10 | L14: 総数 | M14: =COUNTIF(D2:D4000,">=4") -> 902 | N14: =COUNTIF(F2:F4000,">=1") -> 423 | O14: =COUNTIF(G2:G4000,">=0") -> 92 | P14: =COUNTIFS(H2:H4000,">=1") -> 15 | Q14: =COUNTIF(J2:J4000,">=0") -> 24
A15: ）はスピルバーグのシナリオ力量の無さの証拠 | B15: 1 | C15: 2 | D15: 1 | E15: 1 | F15: -1 | G15: -10 | H15: -1 | I15: -10 | J15: -10 | L15: 一致数 | N15: =COUNTIFS(D2:D4000,">=4",F2:F4000,">=1") -> 256 | O15: =COUNTIFS(D2:D4000,">=4",G2:G4000,">=1") -> 56 | P15: =COUNTIFS(D2:D4000,">=4",H2:H4000,">=1") -> 10 | Q15: =COUNTIFS(D2:D4000,">=4",J2:J4000,">=0") -> 14
A16: 役者陣も個性豊かな芸達者でさすがという所 | B16: 5 | C16: 4 | D16: 4 | E16: 5 | F16: -1 | G16: -10 | H16: -1 | I16: -10 | J16: -10 | L16: 適合率 | N16: =N15/N14 -> 0.60520095 | O16: =O15/O14 -> 0.60869565 | P16: =P15/P14 -> 0.66666667 | Q16: =Q15/Q14 -> 0.58333333
A17: 超優良なアドベンチャー映画に7点献上 | B17: 5 | C17: 4 | D17: 5 | E17: 5 | F17: -1 | G17: -10 | H17: -1 | I17: -10 | J17: -10 | L17: 再現率 | N17: =N15/M14 -> 0.28381375 | O17: =O15/M14 -> 0.062084257 | P17: =P15/M14 -> 0.011086475 | Q17: =Q15/M14 -> 0.015521064
A18: 配役も好き | B18: 4 | C18: 1 | D18: 1 | E18: 3 | F18: -1 | G18: -10 | H18: -1 | I18: -10 | J18: -10 | L18: F値 | N18: =(2*N16*N17)/(N16+N17) -> 0.38641509 | O18: =(2*O16*O17)/(O16+O17) -> 0.11267606 | P18: =(2*P16*P17)/(P16+P17) -> 0.021810251 | Q18: =(2*Q16*Q17)/(Q16+Q17) -> 0.030237581
A19: 」と、お互いの顔を見つめ合ってしまいました | B19: 1 | C19: 1 | D19: 1 | E19: 1 | F19: -1 | G19: -10 | H19: -1 | I19: -10 | J19: -10
A20: ストーリーは確かにちょっとアレでしたが、初めて観た時の感動はかなりのものでした | B20: 4 | C20: 4 | D20: 5 | E20: 5 | F20: 1 | G20: -10 | H20: -1 | I20: -10 | J20: -10
A21: 当時映画館で見たときには度肝を抜かれた（古い表現だぁ）単純な娯楽作品なんだけど、遺伝子操作を行うことへの警鐘にも触れていて多面的に楽しめるお気軽作品 | B21: 5 | C21: 5 | D21: 5 | E21: 5 | F21: -1 | G21: -10 | H21: -1 | I21: -10 | J21: -10
A22: だから大人になった自分は、そんな子供心があった自分を今でも覚えていられるのはそのとき出会った映画のおかげなんですよね | B22: 4 | C22: 3 | D22: 4 | E22: 4 | F22: 1 | G22: -10 | H22: -1 | I22: -10 | J22: -10
A23: こうゆうのを「娯楽作品っ | B23: 1 | C23: 1 | D23: 1 | E23: 1 | F23: -1 | G23: -10 | H23: -1 | I23: -10 | J23: -10
A24: もっともストーリーはハラハラドキドキでちっとも安心できませんけどね | B24: 2 | C24: 4 | D24: 2 | E24: 1 | F24: 1 | G24: -10 | H24: -1 | I24: -10 | J24: -10
A25: 良くまとまった作品だと思います | B25: 4 | C25: 1 | D25: 1 | E25: 2 | F25: -1 | G25: -10 | H25: -1 | I25: -10 | J25: -10
A26: スピルバーグ最高 | B26: 4 | C26: 1 | D26: 2 | E26: 2 | F26: -1 | G26: -10 | H26: -1 | I26: -10 | J26: -10
A27: 観ててあのリアルな感じがストレートに伝わってきた | B27: 5 | C27: 4 | D27: 2 | E27: 3 | F27: -1 | G27: -10 | H27: -1 | I27: -10 | J27: -10
A28: 子供が良かったです | B28: 4 | C28: 1 | D28: 1 | E28: 1 | F28: -1 | G28: -10 | H28: -1 | I28: -10 | J28: -10
A29: というかこれみたら、ああ・・当時はこんなだったのかなあ、と素直に信じれます | B29: 3 | C29: 3 | D29: 3 | E29: 2 | F29: -1 | G29: -10 | H29: -1 | I29: -10 | J29: -10
A30: 満点です | B30: 5 | C30: 1 | D30: 1 | E30: 1 | F30: -1 | G30: -10 | H30: -1 | I30: -10 | J30: -10
... A1675: 映画の世界でそんな難題に挑み、奇跡的に満足できる商品を作ってしまったのが本作 | B1675: 5 | C1675: 4 | D1675: 5 | E1675: 5 | F1675: 1 | G1675: -10 | H1675: -1 | I1675: -10 | J1675: -10

Sheet 200
A1: レビュー文 | B1: 映画を肯定的に評価している | C1: 映画の特徴を表している | D1: 映画を推薦しているレビューである | E1: 映画を見たいと思えるレビューである | F1: Polarityチェックの結果 | G1: SVMによる分類結果 | H1: PolarityチェックとSVMの組み合わせ | I1: ユーザのレビューに対する評価を用いたSVMの場合.criteria = 3 | J1: ユーザのレビューに対する評価を用いたSVMの場合.criteria = 4
A2: 日本人だったら、あれ程には勉強せぬまま作品化してしまうのではないか、という想いが湧きました | B2: 2 | C2: 1 | D2: 2 | E2: 1 | F2: 1 | G2: -10 | H2: -1 | I2: -10 | J2: -10
A3: テンポの良さ、キャラクターの個性、観客を最後まで楽しませようというエンターテイメント魂に感服いたします | B3: 5 | C3: 5 | D3: 5 | E3: 4 | F3: -1 | G3: -10 | H3: -1 | I3: -10 | J3: -10 | L3: Criteria = 3
A4: 特撮を含めて映像センスは素晴らしいが監督自身がそれに酔っているようで『この映画凄いでしょう』と言っているみたいに感じる | B4: 2 | C4: 5 | D4: 2 | E4: 3 | F4: -1 | G4: -10 | H4: -1 | I4: -10 | J4: -10 | M4: 推薦文として認識された文 | N4: Polarityチェックの結果 | O4: SVMによる分類結果 | P4: PolarityチェックとSVM | Q4: ユーザの評価を用いたSVM
A5: ＤＶＤを買って結構頻繁に観てるけどその度にわくわくと楽しい気分にさせてくれる映画 | B5: 5 | C5: 2 | D5: 4 | E5: 5 | F5: -1 | G5: -10 | H5: -1 | I5: -10 | J5: -10 | L5: 総数 | M5: =COUNTIF(D2:D4000,">=3") -> 1250 | N5: =COUNTIF(F2:F4000,">=1") -> 423 | O5: =COUNTIF(G2:G4000,">=0") -> 90 | P5: =COUNTIFS(H2:H4000,">=0") -> 15 | Q5: =COUNTIF(I2:I4000,">=0") -> 30
A6: やっぱ、ラプターが天井目掛けて飛びあがるシーンと、T-REXがジープを追いかけてそれがミラーに映るシーンが一番印象深いです | B6: 4 | C6: 5 | D6: 3 | E6: 5 | F6: 1 | G6: -10 | H6: -1 | I6: -10 | J6: -10 | L6: 一致数 | N6: =COUNTIFS(D2:D4000,">=3",F2:F4000,">=1") -> 327 | O6: =COUNTIFS(D2:D4000,">=3",G2:G4000,">=1") -> 77 | P6: =COUNTIFS(D2:D4000,">=3",H2:H4000,">=1") -> 14 | Q6: =COUNTIFS(D2:D4000,">=3",I2:I4000,">=0") -> 29
A7: コレは名作じゃ | B7: 5 | C7: 1 | D7: 1 | E7: 2 | F7: -1 | G7: -10 | H7: -1 | I7: -10 | J7: -10 | L7: 適合率 | N7: =N6/N5 -> 0.77304965 | O7: =O6/O5 -> 0.85555556 | P7: =P6/P5 -> 0.93333333 | Q7: =Q6/Q5 -> 0.96666667
A8: 内容にも破鎖がなく、安心して見られました | B8: 4 | C8: 1 | D8: 2 | E8: 2 | F8: -1 | G8: -10 | H8: -1 | I8: -10 | J8: -10 | L8: 再現率 | N8: =N6/M5 -> 0.2616 | O8: =O6/M5 -> 0.0616 | P8: =P6/M5 -> 0.0112 | Q8: =Q6/M5 -> 0.0232
A9: 曲が美しい | B9: 5 | C9: 1 | D9: 1 | E9: 2 | F9: -1 | G9: -10 | H9: -1 | I9: -10 | J9: -10 | L9: F値 | N9: =(2*N7*N8)/(N7+N8) -> 0.39091452 | O9: =(2*O7*O8)/(O7+O8) -> 0.11492537 | P9: =(2*P7*P8)/(P7+P8) -> 0.022134387 | Q9: =(2*Q7*Q8)/(Q7+Q8) -> 0.0453125
A10: 子役の演技がいいね | B10: 5 | C10: 3 | D10: 3 | E10: 4 | F10: -1 | G10: -10 | H10: -1 | I10: -10 | J10: -10
A11: 誰も見たこともない古代の映像を実にリアル | B11: 4 | C11: 4 | D11: 3 | E11: 4 | F11: -1 | G11: -10 | H11: -1 | I11: -10 | J11: -10
A12: でも迫力あってよかったです | B12: 5 | C12: 4 | D12: 4 | E12: 4 | F12: -1 | G12: -10 | H12: -1 | I12: -10 | J12: -10 | L12: Criteria = 4
A13: 恐竜好きの僕にはラプターも良いけどアロサウルスを出して欲しかった | B13: 2 | C13: 3 | D13: 2 | E13: 2 | F13: -1 | G13: 10 | H13: -1 | I13: -8 | J13: -10 | M13: 推薦文として認識された文 | N13: Polarityチェックの結果 | O13: SVMによる分類結果 | P13: PolarityチェックとSVM | Q13: ユーザの評価を用いたSVM
A14: テンポも速いしいいと思う | B14: 3 | C14: 4 | D14: 2 | E14: 4 | F14: -1 | G14: -10 | H14: -1 | I14: -10 | J14: -10 | L14: 総数 | M14: =COUNTIF(D2:D4000,">=4") -> 902 | N14: =COUNTIF(F2:F4000,">=1") -> 423 | O14: =COUNTIF(G2:G4000,">=0") -> 90 | P14: =COUNTIFS(H2:H4000,">=1") -> 15 | Q14: =COUNTIF(J2:J4000,">=0") -> 23
A15: ）はスピルバーグのシナリオ力量の無さの証拠 | B15: 1 | C15: 2 | D15: 1 | E15: 1 | F15: -1 | G15: -10 | H15: -1 | I15: -10 | J15: -10 | L15: 一致数 | N15: =COUNTIFS(D2:D4000,">=4",F2:F4000,">=1") -> 256 | O15: =COUNTIFS(D2:D4000,">=4",G2:G4000,">=1") -> 56 | P15: =COUNTIFS(D2:D4000,">=4",H2:H4000,">=1") -> 10 | Q15: =COUNTIFS(D2:D4000,">=4",J2:J4000,">=0") -> 13
A16: 役者陣も個性豊かな芸達者でさすがという所 | B16: 5 | C16: 4 | D16: 4 | E16: 5 | F16: -1 | G16: -10 | H16: -1 | I16: -10 | J16: -10 | L16: 適合率 | N16: =N15/N14 -> 0.60520095 | O16: =O15/O14 -> 0.62222222 | P16: =P15/P14 -> 0.66666667 | Q16: =Q15/Q14 -> 0.56521739
A17: 超優良なアドベンチャー映画に7点献上 | B17: 5 | C17: 4 | D17: 5 | E17: 5 | F17: -1 | G17: -10 | H17: -1 | I17: -10 | J17: -10 | L17: 再現率 | N17: =N15/M14 -> 0.28381375 | O17: =O15/M14 -> 0.062084257 | P17: =P15/M14 -> 0.011086475 | Q17: =Q15/M14 -> 0.014412417
A18: 配役も好き | B18: 4 | C18: 1 | D18: 1 | E18: 3 | F18: -1 | G18: -10 | H18: -1 | I18: -10 | J18: -10 | L18: F値 | N18: =(2*N16*N17)/(N16+N17) -> 0.38641509 | O18: =(2*O16*O17)/(O16+O17) -> 0.11290323 | P18: =(2*P16*P17)/(P16+P17) -> 0.021810251 | Q18: =(2*Q16*Q17)/(Q16+Q17) -> 0.028108108
A19: 」と、お互いの顔を見つめ合ってしまいました | B19: 1 | C19: 1 | D19: 1 | E19: 1 | F19: -1 | G19: -10 | H19: -1 | I19: -10 | J19: -10
A20: ストーリーは確かにちょっとアレでしたが、初めて観た時の感動はかなりのものでした | B20: 4 | C20: 4 | D20: 5 | E20: 5 | F20: 1 | G20: -10 | H20: -1 | I20: -10 | J20: -10
A21: 当時映画館で見たときには度肝を抜かれた（古い表現だぁ）単純な娯楽作品なんだけど、遺伝子操作を行うことへの警鐘にも触れていて多面的に楽しめるお気軽作品 | B21: 5 | C21: 5 | D21: 5 | E21: 5 | F21: -1 | G21: -10 | H21: -1 | I21: -10 | J21: -10
A22: だから大人になった自分は、そんな子供心があった自分を今でも覚えていられるのはそのとき出会った映画のおかげなんですよね | B22: 4 | C22: 3 | D22: 4 | E22: 4 | F22: 1 | G22: -10 | H22: -1 | I22: -10 | J22: -10
A23: こうゆうのを「娯楽作品っ | B23: 1 | C23: 1 | D23: 1 | E23: 1 | F23: -1 | G23: -10 | H23: -1 | I23: -10 | J23: -10
A24: もっともストーリーはハラハラドキドキでちっとも安心できませんけどね | B24: 2 | C24: 4 | D24: 2 | E24: 1 | F24: 1 | G24: -10 | H24: -1 | I24: -10 | J24: -10
A25: 良くまとまった作品だと思います | B25: 4 | C25: 1 | D25: 1 | E25: 2 | F25: -1 | G25: -10 | H25: -1 | I25: -10 | J25: -10
A26: スピルバーグ最高 | B26: 4 | C26: 1 | D26: 2 | E26: 2 | F26: -1 | G26: -10 | H26: -1 | I26: -10 | J26: -10
A27: 観ててあのリアルな感じがストレートに伝わってきた | B27: 5 | C27: 4 | D27: 2 | E27: 3 | F27: -1 | G27: -10 | H27: -1 | I27: -10 | J27: -10
A28: 子供が良かったです | B28: 4 | C28: 1 | D28: 1 | E28: 1 | F28: -1 | G28: -10 | H28: -1 | I28: -10 | J28: -10
A29: というかこれみたら、ああ・・当時はこんなだったのかなあ、と素直に信じれます | B29: 3 | C29: 3 | D29: 3 | E29: 2 | F29: -1 | G29: -10 | H29: -1 | I29: -10 | J29: -10
A30: 満点です | B30: 5 | C30: 1 | D30: 1 | E30: 1 | F30: -1 | G30: -10 | H30: -1 | I30: -10 | J30: -10
... A1675: 映画の世界でそんな難題に挑み、奇跡的に満足できる商品を作ってしまったのが本作 | B1675: 5 | C1675: 4 | D1675: 5 | E1675: 5 | F1675: 1 | G1675: -10 | H1675: -1 | I1675: -10 | J1675: -10

Sheet 250
A1: レビュー文 | B1: 映画を肯定的に評価している | C1: 映画の特徴を表している | D1: 映画を推薦しているレビューである | E1: 映画を見たいと思えるレビューである | F1: Polarityチェックの結果 | G1: SVMによる分類結果 | H1: PolarityチェックとSVMの組み合わせ | I1: ユーザのレビューに対する評価を用いたSVMの場合.criteria = 3 | J1: ユーザのレビューに対する評価を用いたSVMの場合.criteria = 4
A2: 日本人だったら、あれ程には勉強せぬまま作品化してしまうのではないか、という想いが湧きました | B2: 2 | C2: 1 | D2: 2 | E2: 1 | F2: 1 | G2: -10 | H2: -1 | I2: -10 | J2: -10
A3: テンポの良さ、キャラクターの個性、観客を最後まで楽しませようというエンターテイメント魂に感服いたします | B3: 5 | C3: 5 | D3: 5 | E3: 4 | F3: -1 | G3: -10 | H3: -1 | I3: -10 | J3: -10 | L3: Criteria = 3
A4: 特撮を含めて映像センスは素晴らしいが監督自身がそれに酔っているようで『この映画凄いでしょう』と言っているみたいに感じる | B4: 2 | C4: 5 | D4: 2 | E4: 3 | F4: -1 | G4: -10 | H4: -1 | I4: -10 | J4: -10 | M4: 推薦文として認識された文 | N4: Polarityチェックの結果 | O4: SVMによる分類結果 | P4: PolarityチェックとSVM | Q4: ユーザの評価を用いたSVM
A5: ＤＶＤを買って結構頻繁に観てるけどその度にわくわくと楽しい気分にさせてくれる映画 | B5: 5 | C5: 2 | D5: 4 | E5: 5 | F5: -1 | G5: -10 | H5: -1 | I5: -10 | J5: -10 | L5: 総数 | M5: =COUNTIF(D2:D4000,">=3") -> 1250 | N5: =COUNTIF(F2:F4000,">=1") -> 423 | O5: =COUNTIF(G2:G4000,">=0") -> 100 | P5: =COUNTIFS(H2:H4000,">=0") -> 15 | Q5: =COUNTIF(I2:I4000,">=0") -> 38
A6: やっぱ、ラプターが天井目掛けて飛びあがるシーンと、T-REXがジープを追いかけてそれがミラーに映るシーンが一番印象深いです | B6: 4 | C6: 5 | D6: 3 | E6: 5 | F6: 1 | G6: -10 | H6: -1 | I6: -10 | J6: -10 | L6: 一致数 | N6: =COUNTIFS(D2:D4000,">=3",F2:F4000,">=1") -> 327 | O6: =COUNTIFS(D2:D4000,">=3",G2:G4000,">=1") -> 77 | P6: =COUNTIFS(D2:D4000,">=3",H2:H4000,">=1") -> 14 | Q6: =COUNTIFS(D2:D4000,">=3",I2:I4000,">=0") -> 36
A7: コレは名作じゃ | B7: 5 | C7: 1 | D7: 1 | E7: 2 | F7: -1 | G7: -10 | H7: -1 | I7: -10 | J7: -10 | L7: 適合率 | N7: =N6/N5 -> 0.77304965 | O7: =O6/O5 -> 0.77 | P7: =P6/P5 -> 0.93333333 | Q7: =Q6/Q5 -> 0.94736842
A8: 内容にも破鎖がなく、安心して見られました | B8: 4 | C8: 1 | D8: 2 | E8: 2 | F8: -1 | G8: -10 | H8: -1 | I8: -10 | J8: -10 | L8: 再現率 | N8: =N6/M5 -> 0.2616 | O8: =O6/M5 -> 0.0616 | P8: =P6/M5 -> 0.0112 | Q8: =Q6/M5 -> 0.0288
A9: 曲が美しい | B9: 5 | C9: 1 | D9: 1 | E9: 2 | F9: -1 | G9: -10 | H9: -1 | I9: -10 | J9: -10 | L9: F値 | N9: =(2*N7*N8)/(N7+N8) -> 0.39091452 | O9: =(2*O7*O8)/(O7+O8) -> 0.11407407 | P9: =(2*P7*P8)/(P7+P8) -> 0.022134387 | Q9: =(2*Q7*Q8)/(Q7+Q8) -> 0.055900621
A10: 子役の演技がいいね | B10: 5 | C10: 3 | D10: 3 | E10: 4 | F10: -1 | G10: -10 | H10: -1 | I10: -10 | J10: -10
A11: 誰も見たこともない古代の映像を実にリアル | B11: 4 | C11: 4 | D11: 3 | E11: 4 | F11: -1 | G11: -10 | H11: -1 | I11: -10 | J11: -10
A12: でも迫力あってよかったです | B12: 5 | C12: 4 | D12: 4 | E12: 4 | F12: -1 | G12: -10 | H12: -1 | I12: -10 | J12: -10 | L12: Criteria = 4
A13: 恐竜好きの僕にはラプターも良いけどアロサウルスを出して欲しかった | B13: 2 | C13: 3 | D13: 2 | E13: 2 | F13: -1 | G13: 10 | H13: -1 | I13: -6 | J13: -10 | M13: 推薦文として認識された文 | N13: Polarityチェックの結果 | O13: SVMによる分類結果 | P13: PolarityチェックとSVM | Q13: ユーザの評価を用いたSVM
A14: テンポも速いしいいと思う | B14: 3 | C14: 4 | D14: 2 | E14: 4 | F14: -1 | G14: -10 | H14: -1 | I14: -10 | J14: -10 | L14: 総数 | M14: =COUNTIF(D2:D4000,">=4") -> 902 | N14: =COUNTIF(F2:F4000,">=1") -> 423 | O14: =COUNTIF(G2:G4000,">=0") -> 100 | P14: =COUNTIFS(H2:H4000,">=1") -> 15 | Q14: =COUNTIF(J2:J4000,">=0") -> 51
A15: ）はスピルバーグのシナリオ力量の無さの証拠 | B15: 1 | C15: 2 | D15: 1 | E15: 1 | F15: -1 | G15: -10 | H15: -1 | I15: -10 | J15: -10 | L15: 一致数 | N15: =COUNTIFS(D2:D4000,">=4",F2:F4000,">=1") -> 256 | O15: =COUNTIFS(D2:D4000,">=4",G2:G4000,">=1") -> 56 | P15: =COUNTIFS(D2:D4000,">=4",H2:H4000,">=1") -> 10 | Q15: =COUNTIFS(D2:D4000,">=4",J2:J4000,">=0") -> 30
A16: 役者陣も個性豊かな芸達者でさすがという所 | B16: 5 | C16: 4 | D16: 4 | E16: 5 | F16: -1 | G16: -10 | H16: -1 | I16: -10 | J16: -10 | L16: 適合率 | N16: =N15/N14 -> 0.60520095 | O16: =O15/O14 -> 0.56 | P16: =P15/P14 -> 0.66666667 | Q16: =Q15/Q14 -> 0.58823529
A17: 超優良なアドベンチャー映画に7点献上 | B17: 5 | C17: 4 | D17: 5 | E17: 5 | F17: -1 | G17: -10 | H17: -1 | I17: -10 | J17: -10 | L17: 再現率 | N17: =N15/M14 -> 0.28381375 | O17: =O15/M14 -> 0.062084257 | P17: =P15/M14 -> 0.011086475 | Q17: =Q15/M14 -> 0.033259424
A18: 配役も好き | B18: 4 | C18: 1 | D18: 1 | E18: 3 | F18: -1 | G18: -10 | H18: -1 | I18: -10 | J18: -10 | L18: F値 | N18: =(2*N16*N17)/(N16+N17) -> 0.38641509 | O18: =(2*O16*O17)/(O16+O17) -> 0.11177645 | P18: =(2*P16*P17)/(P16+P17) -> 0.021810251 | Q18: =(2*Q16*Q17)/(Q16+Q17) -> 0.062959077
A19: 」と、お互いの顔を見つめ合ってしまいました | B19: 1 | C19: 1 | D19: 1 | E19: 1 | F19: -1 | G19: -10 | H19: -1 | I19: -10 | J19: -10
A20: ストーリーは確かにちょっとアレでしたが、初めて観た時の感動はかなりのものでした | B20: 4 | C20: 4 | D20: 5 | E20: 5 | F20: 1 | G20: -10 | H20: -1 | I20: -10 | J20: -10
A21: 当時映画館で見たときには度肝を抜かれた（古い表現だぁ）単純な娯楽作品なんだけど、遺伝子操作を行うことへの警鐘にも触れていて多面的に楽しめるお気軽作品 | B21: 5 | C21: 5 | D21: 5 | E21: 5 | F21: -1 | G21: -10 | H21: -1 | I21: -10 | J21: -10
A22: だから大人になった自分は、そんな子供心があった自分を今でも覚えていられるのはそのとき出会った映画のおかげなんですよね | B22: 4 | C22: 3 | D22: 4 | E22: 4 | F22: 1 | G22: -10 | H22: -1 | I22: -10 | J22: -10
A23: こうゆうのを「娯楽作品っ | B23: 1 | C23: 1 | D23: 1 | E23: 1 | F23: -1 | G23: -10 | H23: -1 | I23: -10 | J23: -10
A24: もっともストーリーはハラハラドキドキでちっとも安心できませんけどね | B24: 2 | C24: 4 | D24: 2 | E24: 1 | F24: 1 | G24: -10 | H24: -1 | I24: -10 | J24: -10
A25: 良くまとまった作品だと思います | B25: 4 | C25: 1 | D25: 1 | E25: 2 | F25: -1 | G25: -10 | H25: -1 | I25: -10 | J25: -10
A26: スピルバーグ最高 | B26: 4 | C26: 1 | D26: 2 | E26: 2 | F26: -1 | G26: -10 | H26: -1 | I26: -10 | J26: -10
A27: 観ててあのリアルな感じがストレートに伝わってきた | B27: 5 | C27: 4 | D27: 2 | E27: 3 | F27: -1 | G27: -10 | H27: -1 | I27: -10 | J27: -10
A28: 子供が良かったです | B28: 4 | C28: 1 | D28: 1 | E28: 1 | F28: -1 | G28: -10 | H28: -1 | I28: -10 | J28: -10
A29: というかこれみたら、ああ・・当時はこんなだったのかなあ、と素直に信じれます | B29: 3 | C29: 3 | D29: 3 | E29: 2 | F29: -1 | G29: -10 | H29: -1 | I29: -10 | J29: -10
A30: 満点です | B30: 5 | C30: 1 | D30: 1 | E30: 1 | F30: -1 | G30: -10 | H30: -1 | I30: -10 | J30: -10
... A1675: 映画の世界でそんな難題に挑み、奇跡的に満足できる商品を作ってしまったのが本作 | B1675: 5 | C1675: 4 | D1675: 5 | E1675: 5 | F1675: 1 | G1675: -10 | H1675: -1 | I1675: -10 | J1675: -10

Sheet 300
A1: レビュー文 | B1: 映画を肯定的に評価している | C1: 映画の特徴を表している | D1: 映画を推薦しているレビューである | E1: 映画を見たいと思えるレビューである | F1: Polarityチェックの結果 | G1: SVMによる分類結果 | H1: PolarityチェックとSVMの組み合わせ | I1: ユーザのレビューに対する評価を用いたSVMの場合.criteria = 3 | J1: ユーザのレビューに対する評価を用いたSVMの場合.criteria = 4
A2: 日本人だったら、あれ程には勉強せぬまま作品化してしまうのではないか、という想いが湧きました | B2: 2 | C2: 1 | D2: 2 | E2: 1 | F2: 1 | G2: -10 | H2: -1 | I2: -10 | J2: -10
A3: テンポの良さ、キャラクターの個性、観客を最後まで楽しませようというエンターテイメント魂に感服いたします | B3: 5 | C3: 5 | D3: 5 | E3: 4 | F3: -1 | G3: -10 | H3: -1 | I3: -10 | J3: -10 | L3: Criteria = 3
A4: 特撮を含めて映像センスは素晴らしいが監督自身がそれに酔っているようで『この映画凄いでしょう』と言っているみたいに感じる | B4: 2 | C4: 5 | D4: 2 | E4: 3 | F4: -1 | G4: -10 | H4: -1 | I4: -10 | J4: -10 | M4: 推薦文として認識された文 | N4: Polarityチェックの結果 | O4: SVMによる分類結果 | P4: PolarityチェックとSVM | Q4: ユーザの評価を用いたSVM
A5: ＤＶＤを買って結構頻繁に観てるけどその度にわくわくと楽しい気分にさせてくれる映画 | B5: 5 | C5: 2 | D5: 4 | E5: 5 | F5: -1 | G5: -10 | H5: -1 | I5: -10 | J5: -10 | L5: 総数 | M5: =COUNTIF(D2:D4000,">=3") -> 1250 | N5: =COUNTIF(F2:F4000,">=1") -> 423 | O5: =COUNTIF(G2:G4000,">=0") -> 90 | P5: =COUNTIFS(H2:H4000,">=0") -> 15 | Q5: =COUNTIF(I2:I4000,">=0") -> 39
A6: やっぱ、ラプターが天井目掛けて飛びあがるシーンと、T-REXがジープを追いかけてそれがミラーに映るシーンが一番印象深いです | B6: 4 | C6: 5 | D6: 3 | E6: 5 | F6: 1 | G6: -10 | H6: -1 | I6: -10 | J6: -10 | L6: 一致数 | N6: =COUNTIFS(D2:D4000,">=3",F2:F4000,">=1") -> 327 | O6: =COUNTIFS(D2:D4000,">=3",G2:G4000,">=1") -> 77 | P6: =COUNTIFS(D2:D4000,">=3",H2:H4000,">=1") -> 14 | Q6: =COUNTIFS(D2:D4000,">=3",I2:I4000,">=0") -> 37
A7: コレは名作じゃ | B7: 5 | C7: 1 | D7: 1 | E7: 2 | F7: -1 | G7: -10 | H7: -1 | I7: -10 | J7: -10 | L7: 適合率 | N7: =N6/N5 -> 0.77304965 | O7: =O6/O5 -> 0.85555556 | P7: =P6/P5 -> 0.93333333 | Q7: =Q6/Q5 -> 0.94871795
A8: 内容にも破鎖がなく、安心して見られました | B8: 4 | C8: 1 | D8: 2 | E8: 2 | F8: -1 | G8: -10 | H8: -1 | I8: -10 | J8: -10 | L8: 再現率 | N8: =N6/M5 -> 0.2616 | O8: =O6/M5 -> 0.0616 | P8: =P6/M5 -> 0.0112 | Q8: =Q6/M5 -> 0.0296
A9: 曲が美しい | B9: 5 | C9: 1 | D9: 1 | E9: 2 | F9: -1 | G9: -10 | H9: -1 | I9: -10 | J9: -10 | L9: F値 | N9: =(2*N7*N8)/(N7+N8) -> 0.39091452 | O9: =(2*O7*O8)/(O7+O8) -> 0.11492537 | P9: =(2*P7*P8)/(P7+P8) -> 0.022134387 | Q9: =(2*Q7*Q8)/(Q7+Q8) -> 0.057408844
A10: 子役の演技がいいね | B10: 5 | C10: 3 | D10: 3 | E10: 4 | F10: -1 | G10: -10 | H10: -1 | I10: -10 | J10: -10
A11: 誰も見たこともない古代の映像を実にリアル | B11: 4 | C11: 4 | D11: 3 | E11: 4 | F11: -1 | G11: -10 | H11: -1 | I11: -10 | J11: -10
A12: でも迫力あってよかったです | B12: 5 | C12: 4 | D12: 4 | E12: 4 | F12: -1 | G12: -10 | H12: -1 | I12: -10 | J12: -10 | L12: Criteria = 4
A13: 恐竜好きの僕にはラプターも良いけどアロサウルスを出して欲しかった | B13: 2 | C13: 3 | D13: 2 | E13: 2 | F13: -1 | G13: 10 | H13: -1 | I13: -10 | J13: -10 | M13: 推薦文として認識された文 | N13: Polarityチェックの結果 | O13: SVMによる分類結果 | P13: PolarityチェックとSVM | Q13: ユーザの評価を用いたSVM
A14: テンポも速いしいいと思う | B14: 3 | C14: 4 | D14: 2 | E14: 4 | F14: -1 | G14: -10 | H14: -1 | I14: -10 | J14: -10 | L14: 総数 | M14: =COUNTIF(D2:D4000,">=4") -> 902 | N14: =COUNTIF(F2:F4000,">=1") -> 423 | O14: =COUNTIF(G2:G4000,">=0") -> 90 | P14: =COUNTIFS(H2:H4000,">=1") -> 15 | Q14: =COUNTIF(J2:J4000,">=0") -> 51
A15: ）はスピルバーグのシナリオ力量の無さの証拠 | B15: 1 | C15: 2 | D15: 1 | E15: 1 | F15: -1 | G15: -10 | H15: -1 | I15: -10 | J15: -10 | L15: 一致数 | N15: =COUNTIFS(D2:D4000,">=4",F2:F4000,">=1") -> 256 | O15: =COUNTIFS(D2:D4000,">=4",G2:G4000,">=1") -> 56 | P15: =COUNTIFS(D2:D4000,">=4",H2:H4000,">=1") -> 10 | Q15: =COUNTIFS(D2:D4000,">=4",J2:J4000,">=0") -> 30
A16: 役者陣も個性豊かな芸達者でさすがという所 | B16: 5 | C16: 4 | D16: 4 | E16: 5 | F16: -1 | G16: -10 | H16: -1 | I16: -10 | J16: -10 | L16: 適合率 | N16: =N15/N14 -> 0.60520095 | O16: =O15/O14 -> 0.62222222 | P16: =P15/P14 -> 0.66666667 | Q16: =Q15/Q14 -> 0.58823529
A17: 超優良なアドベンチャー映画に7点献上 | B17: 5 | C17: 4 | D17: 5 | E17: 5 | F17: -1 | G17: -10 | H17: -1 | I17: -10 | J17: -10 | L17: 再現率 | N17: =N15/M14 -> 0.28381375 | O17: =O15/M14 -> 0.062084257 | P17: =P15/M14 -> 0.011086475 | Q17: =Q15/M14 -> 0.033259424
A18: 配役も好き | B18: 4 | C18: 1 | D18: 1 | E18: 3 | F18: -1 | G18: -10 | H18: -1 | I18: -10 | J18: -10 | L18: F値 | N18: =(2*N16*N17)/(N16+N17) -> 0.38641509 | O18: =(2*O16*O17)/(O16+O17) -> 0.11290323 | P18: =(2*P16*P17)/(P16+P17) -> 0.021810251 | Q18: =(2*Q16*Q17)/(Q16+Q17) -> 0.062959077
A19: 」と、お互いの顔を見つめ合ってしまいました | B19: 1 | C19: 1 | D19: 1 | E19: 1 | F19: -1 | G19: -10 | H19: -1 | I19: -10 | J19: -10
A20: ストーリーは確かにちょっとアレでしたが、初めて観た時の感動はかなりのものでした | B20: 4 | C20: 4 | D20: 5 | E20: 5 | F20: 1 | G20: -10 | H20: -1 | I20: -10 | J20: -10
A21: 当時映画館で見たときには度肝を抜かれた（古い表現だぁ）単純な娯楽作品なんだけど、遺伝子操作を行うことへの警鐘にも触れていて多面的に楽しめるお気軽作品 | B21: 5 | C21: 5 | D21: 5 | E21: 5 | F21: -1 | G21: -10 | H21: -1 | I21: -10 | J21: -10
A22: だから大人になった自分は、そんな子供心があった自分を今でも覚えていられるのはそのとき出会った映画のおかげなんですよね | B22: 4 | C22: 3 | D22: 4 | E22: 4 | F22: 1 | G22: -10 | H22: -1 | I22: -10 | J22: -10
A23: こうゆうのを「娯楽作品っ | B23: 1 | C23: 1 | D23: 1 | E23: 1 | F23: -1 | G23: -10 | H23: -1 | I23: -10 | J23: -10
A24: もっともストーリーはハラハラドキドキでちっとも安心できませんけどね | B24: 2 | C24: 4 | D24: 2 | E24: 1 | F24: 1 | G24: -10 | H24: -1 | I24: -10 | J24: -10
A25: 良くまとまった作品だと思います | B25: 4 | C25: 1 | D25: 1 | E25: 2 | F25: -1 | G25: -10 | H25: -1 | I25: -10 | J25: -10
A26: スピルバーグ最高 | B26: 4 | C26: 1 | D26: 2 | E26: 2 | F26: -1 | G26: -10 | H26: -1 | I26: -10 | J26: -10
A27: 観ててあのリアルな感じがストレートに伝わってきた | B27: 5 | C27: 4 | D27: 2 | E27: 3 | F27: -1 | G27: -10 | H27: -1 | I27: -10 | J27: -10
A28: 子供が良かったです | B28: 4 | C28: 1 | D28: 1 | E28: 1 | F28: -1 | G28: -10 | H28: -1 | I28: -10 | J28: -10
A29: というかこれみたら、ああ・・当時はこんなだったのかなあ、と素直に信じれます | B29: 3 | C29: 3 | D29: 3 | E29: 2 | F29: -1 | G29: -10 | H29: -1 | I29: -10 | J29: -10
A30: 満点です | B30: 5 | C30: 1 | D30: 1 | E30: 1 | F30: -1 | G30: -10 | H30: -1 | I30: -10 | J30: -10
... A1675: 映画の世界でそんな難題に挑み、奇跡的に満足できる商品を作ってしまったのが本作 | B1675: 5 | C1675: 4 | D1675: 5 | E1675: 5 | F1675: 1 | G1675: -10 | H1675: -1 | I1675: -10 | J1675: -10

Sheet 350
A1: レビュー文 | B1: 映画を肯定的に評価している | C1: 映画の特徴を表している | D1: 映画を推薦しているレビューである | E1: 映画を見たいと思えるレビューである | F1: Polarityチェックの結果 | G1: SVMによる分類結果 | H1: PolarityチェックとSVMの組み合わせ | I1: ユーザのレビューに対する評価を用いたSVMの場合.criteria = 3 | J1: ユーザのレビューに対する評価を用いたSVMの場合.criteria = 4
A2: 日本人だったら、あれ程には勉強せぬまま作品化してしまうのではないか、という想いが湧きました | B2: 2 | C2: 1 | D2: 2 | E2: 1 | F2: 1 | G2: -10 | H2: -1 | I2: -10 | J2: -10
A3: テンポの良さ、キャラクターの個性、観客を最後まで楽しませようというエンターテイメント魂に感服いたします | B3: 5 | C3: 5 | D3: 5 | E3: 4 | F3: -1 | G3: -10 | H3: -1 | I3: -10 | J3: -10 | L3: Criteria = 3
A4: 特撮を含めて映像センスは素晴らしいが監督自身がそれに酔っているようで『この映画凄いでしょう』と言っているみたいに感じる | B4: 2 | C4: 5 | D4: 2 | E4: 3 | F4: -1 | G4: -10 | H4: -1 | I4: -10 | J4: -10 | M4: 推薦文として認識された文 | N4: Polarityチェックの結果 | O4: SVMによる分類結果 | P4: PolarityチェックとSVM | Q4: ユーザの評価を用いたSVM
A5: ＤＶＤを買って結構頻繁に観てるけどその度にわくわくと楽しい気分にさせてくれる映画 | B5: 5 | C5: 2 | D5: 4 | E5: 5 | F5: -1 | G5: -10 | H5: -1 | I5: -10 | J5: -10 | L5: 総数 | M5: =COUNTIF(D2:D4000,">=3") -> 1250 | N5: =COUNTIF(F2:F4000,">=1") -> 423 | O5: =COUNTIF(G2:G4000,">=0") -> 90 | P5: =COUNTIFS(H2:H4000,">=0") -> 15 | Q5: =COUNTIF(I2:I4000,">=0") -> 38
A6: やっぱ、ラプターが天井目掛けて飛びあがるシーンと、T-REXがジープを追いかけてそれがミラーに映るシーンが一番印象深いです | B6: 4 | C6: 5 | D6: 3 | E6: 5 | F6: 1 | G6: -10 | H6: -1 | I6: -10 | J6: -10 | L6: 一致数 | N6: =COUNTIFS(D2:D4000,">=3",F2:F4000,">=1") -> 327 | O6: =COUNTIFS(D2:D4000,">=3",G2:G4000,">=1") -> 77 | P6: =COUNTIFS(D2:D4000,">=3",H2:H4000,">=1") -> 14 | Q6: =COUNTIFS(D2:D4000,">=3",I2:I4000,">=0") -> 36
A7: コレは名作じゃ | B7: 5 | C7: 1 | D7: 1 | E7: 2 | F7: -1 | G7: -10 | H7: -1 | I7: -10 | J7: -10 | L7: 適合率 | N7: =N6/N5 -> 0.77304965 | O7: =O6/O5 -> 0.85555556 | P7: =P6/P5 -> 0.93333333 | Q7: =Q6/Q5 -> 0.94736842
A8: 内容にも破鎖がなく、安心して見られました | B8: 4 | C8: 1 | D8: 2 | E8: 2 | F8: -1 | G8: -10 | H8: -1 | I8: -10 | J8: -10 | L8: 再現率 | N8: =N6/M5 -> 0.2616 | O8: =O6/M5 -> 0.0616 | P8: =P6/M5 -> 0.0112 | Q8: =Q6/M5 -> 0.0288
A9: 曲が美しい | B9: 5 | C9: 1 | D9: 1 | E9: 2 | F9: -1 | G9: -10 | H9: -1 | I9: -10 | J9: -10 | L9: F値 | N9: =(2*N7*N8)/(N7+N8) -> 0.39091452 | O9: =(2*O7*O8)/(O7+O8) -> 0.11492537 | P9: =(2*P7*P8)/(P7+P8) -> 0.022134387 | Q9: =(2*Q7*Q8)/(Q7+Q8) -> 0.055900621
A10: 子役の演技がいいね | B10: 5 | C10: 3 | D10: 3 | E10: 4 | F10: -1 | G10: -10 | H10: -1 | I10: -10 | J10: -10
A11: 誰も見たこともない古代の映像を実にリアル | B11: 4 | C11: 4 | D11: 3 | E11: 4 | F11: -1 | G11: -10 | H11: -1 | I11: -10 | J11: -10
A12: でも迫力あってよかったです | B12: 5 | C12: 4 | D12: 4 | E12: 4 | F12: -1 | G12: -10 | H12: -1 | I12: -10 | J12: -10 | L12: Criteria = 4
A13: 恐竜好きの僕にはラプターも良いけどアロサウルスを出して欲しかった | B13: 2 | C13: 3 | D13: 2 | E13: 2 | F13: -1 | G13: 10 | H13: -1 | I13: -10 | J13: -10 | M13: 推薦文として認識された文 | N13: Polarityチェックの結果 | O13: SVMによる分類結果 | P13: PolarityチェックとSVM | Q13: ユーザの評価を用いたSVM
A14: テンポも速いしいいと思う | B14: 3 | C14: 4 | D14: 2 | E14: 4 | F14: -1 | G14: -10 | H14: -1 | I14: -10 | J14: -10 | L14: 総数 | M14: =COUNTIF(D2:D4000,">=4") -> 902 | N14: =COUNTIF(F2:F4000,">=1") -> 423 | O14: =COUNTIF(G2:G4000,">=0") -> 90 | P14: =COUNTIFS(H2:H4000,">=1") -> 15 | Q14: =COUNTIF(J2:J4000,">=0") -> 52
A15: ）はスピルバーグのシナリオ力量の無さの証拠 | B15: 1 | C15: 2 | D15: 1 | E15: 1 | F15: -1 | G15: -10 | H15: -1 | I15: -10 | J15: -10 | L15: 一致数 | N15: =COUNTIFS(D2:D4000,">=4",F2:F4000,">=1") -> 256 | O15: =COUNTIFS(D2:D4000,">=4",G2:G4000,">=1") -> 56 | P15: =COUNTIFS(D2:D4000,">=4",H2:H4000,">=1") -> 10 | Q15: =COUNTIFS(D2:D4000,">=4",J2:J4000,">=0") -> 31
A16: 役者陣も個性豊かな芸達者でさすがという所 | B16: 5 | C16: 4 | D16: 4 | E16: 5 | F16: -1 | G16: -10 | H16: -1 | I16: -10 | J16: -10 | L16: 適合率 | N16: =N15/N14 -> 0.60520095 | O16: =O15/O14 -> 0.62222222 | P16: =P15/P14 -> 0.66666667 | Q16: =Q15/Q14 -> 0.59615385
A17: 超優良なアドベンチャー映画に7点献上 | B17: 5 | C17: 4 | D17: 5 | E17: 5 | F17: -1 | G17: -10 | H17: -1 | I17: -10 | J17: -10 | L17: 再現率 | N17: =N15/M14 -> 0.28381375 | O17: =O15/M14 -> 0.062084257 | P17: =P15/M14 -> 0.011086475 | Q17: =Q15/M14 -> 0.034368071
A18: 配役も好き | B18: 4 | C18: 1 | D18: 1 | E18: 3 | F18: -1 | G18: -10 | H18: -1 | I18: -10 | J18: -10 | L18: F値 | N18: =(2*N16*N17)/(N16+N17) -> 0.38641509 | O18: =(2*O16*O17)/(O16+O17) -> 0.11290323 | P18: =(2*P16*P17)/(P16+P17) -> 0.021810251 | Q18: =(2*Q16*Q17)/(Q16+Q17) -> 0.064989518
A19: 」と、お互いの顔を見つめ合ってしまいました | B19: 1 | C19: 1 | D19: 1 | E19: 1 | F19: -1 | G19: -10 | H19: -1 | I19: -10 | J19: -10
A20: ストーリーは確かにちょっとアレでしたが、初めて観た時の感動はかなりのものでした | B20: 4 | C20: 4 | D20: 5 | E20: 5 | F20: 1 | G20: -10 | H20: -1 | I20: -10 | J20: -10
A21: 当時映画館で見たときには度肝を抜かれた（古い表現だぁ）単純な娯楽作品なんだけど、遺伝子操作を行うことへの警鐘にも触れていて多面的に楽しめるお気軽作品 | B21: 5 | C21: 5 | D21: 5 | E21: 5 | F21: -1 | G21: -10 | H21: -1 | I21: -10 | J21: -10
A22: だから大人になった自分は、そんな子供心があった自分を今でも覚えていられるのはそのとき出会った映画のおかげなんですよね | B22: 4 | C22: 3 | D22: 4 | E22: 4 | F22: 1 | G22: -10 | H22: -1 | I22: -10 | J22: -10
A23: こうゆうのを「娯楽作品っ | B23: 1 | C23: 1 | D23: 1 | E23: 1 | F23: -1 | G23: -10 | H23: -1 | I23: -10 | J23: -10
A24: もっともストーリーはハラハラドキドキでちっとも安心できませんけどね | B24: 2 | C24: 4 | D24: 2 | E24: 1 | F24: 1 | G24: -10 | H24: -1 | I24: -10 | J24: -10
A25: 良くまとまった作品だと思います | B25: 4 | C25: 1 | D25: 1 | E25: 2 | F25: -1 | G25: -10 | H25: -1 | I25: -10 | J25: -10
A26: スピルバーグ最高 | B26: 4 | C26: 1 | D26: 2 | E26: 2 | F26: -1 | G26: -10 | H26: -1 | I26: -10 | J26: -10
A27: 観ててあのリアルな感じがストレートに伝わってきた | B27: 5 | C27: 4 | D27: 2 | E27: 3 | F27: -1 | G27: -10 | H27: -1 | I27: -10 | J27: -10
A28: 子供が良かったです | B28: 4 | C28: 1 | D28: 1 | E28: 1 | F28: -1 | G28: -10 | H28: -1 | I28: -10 | J28: -10
A29: というかこれみたら、ああ・・当時はこんなだったのかなあ、と素直に信じれます | B29: 3 | C29: 3 | D29: 3 | E29: 2 | F29: -1 | G29: -10 | H29: -1 | I29: -10 | J29: -10
A30: 満点です | B30: 5 | C30: 1 | D30: 1 | E30: 1 | F30: -1 | G30: -10 | H30: -1 | I30: -10 | J30: -10
... A1675: 映画の世界でそんな難題に挑み、奇跡的に満足できる商品を作ってしまったのが本作 | B1675: 5 | C1675: 4 | D1675: 5 | E1675: 5 | F1675: 1 | G1675: -10 | H1675: -1 | I1675: -10 | J1675: -10

Sheet 400
A1: レビュー文 | B1: 映画を肯定的に評価している | C1: 映画の特徴を表している | D1: 映画を推薦しているレビューである | E1: 映画を見たいと思えるレビューである | F1: Polarityチェックの結果 | G1: SVMによる分類結果 | H1: PolarityチェックとSVMの組み合わせ | I1: ユーザのレビューに対する評価を用いたSVMの場合.criteria = 3 | J1: ユーザのレビューに対する評価を用いたSVMの場合.criteria = 4
A2: 日本人だったら、あれ程には勉強せぬまま作品化してしまうのではないか、という想いが湧きました | B2: 2 | C2: 1 | D2: 2 | E2: 1 | F2: 1 | G2: -10 | H2: -1 | I2: -10 | J2: -10
A3: テンポの良さ、キャラクターの個性、観客を最後まで楽しませようというエンターテイメント魂に感服いたします | B3: 5 | C3: 5 | D3: 5 | E3: 4 | F3: -1 | G3: -10 | H3: -1 | I3: -10 | J3: -10 | L3: Criteria = 3
A4: 特撮を含めて映像センスは素晴らしいが監督自身がそれに酔っているようで『この映画凄いでしょう』と言っているみたいに感じる | B4: 2 | C4: 5 | D4: 2 | E4: 3 | F4: -1 | G4: -10 | H4: -1 | I4: -10 | J4: -10 | M4: 推薦文として認識された文 | N4: Polarityチェックの結果 | O4: SVMによる分類結果 | P4: PolarityチェックとSVM | Q4: ユーザの評価を用いたSVM
A5: ＤＶＤを買って結構頻繁に観てるけどその度にわくわくと楽しい気分にさせてくれる映画 | B5: 5 | C5: 2 | D5: 4 | E5: 5 | F5: -1 | G5: -10 | H5: -1 | I5: -10 | J5: -10 | L5: 総数 | M5: =COUNTIF(D2:D4000,">=3") -> 1250 | N5: =COUNTIF(F2:F4000,">=1") -> 423 | O5: =COUNTIF(G2:G4000,">=0") -> 85 | P5: =COUNTIFS(H2:H4000,">=0") -> 14 | Q5: =COUNTIF(I2:I4000,">=0") -> 39
A6: やっぱ、ラプターが天井目掛けて飛びあがるシーンと、T-REXがジープを追いかけてそれがミラーに映るシーンが一番印象深いです | B6: 4 | C6: 5 | D6: 3 | E6: 5 | F6: 1 | G6: -10 | H6: -1 | I6: -10 | J6: -10 | L6: 一致数 | N6: =COUNTIFS(D2:D4000,">=3",F2:F4000,">=1") -> 327 | O6: =COUNTIFS(D2:D4000,">=3",G2:G4000,">=1") -> 71 | P6: =COUNTIFS(D2:D4000,">=3",H2:H4000,">=1") -> 13 | Q6: =COUNTIFS(D2:D4000,">=3",I2:I4000,">=0") -> 37
A7: コレは名作じゃ | B7: 5 | C7: 1 | D7: 1 | E7: 2 | F7: -1 | G7: -10 | H7: -1 | I7: -10 | J7: -10 | L7: 適合率 | N7: =N6/N5 -> 0.77304965 | O7: =O6/O5 -> 0.83529412 | P7: =P6/P5 -> 0.92857143 | Q7: =Q6/Q5 -> 0.94871795
A8: 内容にも破鎖がなく、安心して見られました | B8: 4 | C8: 1 | D8: 2 | E8: 2 | F8: -1 | G8: -10 | H8: -1 | I8: -10 | J8: -10 | L8: 再現率 | N8: =N6/M5 -> 0.2616 | O8: =O6/M5 -> 0.0568 | P8: =P6/M5 -> 0.0104 | Q8: =Q6/M5 -> 0.0296
A9: 曲が美しい | B9: 5 | C9: 1 | D9: 1 | E9: 2 | F9: -1 | G9: -10 | H9: -1 | I9: -10 | J9: -10 | L9: F値 | N9: =(2*N7*N8)/(N7+N8) -> 0.39091452 | O9: =(2*O7*O8)/(O7+O8) -> 0.10636704 | P9: =(2*P7*P8)/(P7+P8) -> 0.02056962 | Q9: =(2*Q7*Q8)/(Q7+Q8) -> 0.057408844
A10: 子役の演技がいいね | B10: 5 | C10: 3 | D10: 3 | E10: 4 | F10: -1 | G10: -10 | H10: -1 | I10: -10 | J10: -10
A11: 誰も見たこともない古代の映像を実にリアル | B11: 4 | C11: 4 | D11: 3 | E11: 4 | F11: -1 | G11: -10 | H11: -1 | I11: -10 | J11: -10
A12: でも迫力あってよかったです | B12: 5 | C12: 4 | D12: 4 | E12: 4 | F12: -1 | G12: -10 | H12: -1 | I12: -10 | J12: -10 | L12: Criteria = 4
A13: 恐竜好きの僕にはラプターも良いけどアロサウルスを出して欲しかった | B13: 2 | C13: 3 | D13: 2 | E13: 2 | F13: -1 | G13: 10 | H13: -1 | I13: -10 | J13: -10 | M13: 推薦文として認識された文 | N13: Polarityチェックの結果 | O13: SVMによる分類結果 | P13: PolarityチェックとSVM | Q13: ユーザの評価を用いたSVM
A14: テンポも速いしいいと思う | B14: 3 | C14: 4 | D14: 2 | E14: 4 | F14: -1 | G14: -10 | H14: -1 | I14: -10 | J14: -10 | L14: 総数 | M14: =COUNTIF(D2:D4000,">=4") -> 902 | N14: =COUNTIF(F2:F4000,">=1") -> 423 | O14: =COUNTIF(G2:G4000,">=0") -> 85 | P14: =COUNTIFS(H2:H4000,">=1") -> 14 | Q14: =COUNTIF(J2:J4000,">=0") -> 51
A15: ）はスピルバーグのシナリオ力量の無さの証拠 | B15: 1 | C15: 2 | D15: 1 | E15: 1 | F15: -1 | G15: -10 | H15: -1 | I15: -10 | J15: -10 | L15: 一致数 | N15: =COUNTIFS(D2:D4000,">=4",F2:F4000,">=1") -> 256 | O15: =COUNTIFS(D2:D4000,">=4",G2:G4000,">=1") -> 52 | P15: =COUNTIFS(D2:D4000,">=4",H2:H4000,">=1") -> 9 | Q15: =COUNTIFS(D2:D4000,">=4",J2:J4000,">=0") -> 30
A16: 役者陣も個性豊かな芸達者でさすがという所 | B16: 5 | C16: 4 | D16: 4 | E16: 5 | F16: -1 | G16: -10 | H16: -1 | I16: -10 | J16: -10 | L16: 適合率 | N16: =N15/N14 -> 0.60520095 | O16: =O15/O14 -> 0.61176471 | P16: =P15/P14 -> 0.64285714 | Q16: =Q15/Q14 -> 0.58823529
A17: 超優良なアドベンチャー映画に7点献上 | B17: 5 | C17: 4 | D17: 5 | E17: 5 | F17: -1 | G17: -10 | H17: -1 | I17: -10 | J17: -10 | L17: 再現率 | N17: =N15/M14 -> 0.28381375 | O17: =O15/M14 -> 0.057649667 | P17: =P15/M14 -> 0.0099778271 | Q17: =Q15/M14 -> 0.033259424
A18: 配役も好き | B18: 4 | C18: 1 | D18: 1 | E18: 3 | F18: -1 | G18: -10 | H18: -1 | I18: -10 | J18: -10 | L18: F値 | N18: =(2*N16*N17)/(N16+N17) -> 0.38641509 | O18: =(2*O16*O17)/(O16+O17) -> 0.10536981 | P18: =(2*P16*P17)/(P16+P17) -> 0.019650655 | Q18: =(2*Q16*Q17)/(Q16+Q17) -> 0.062959077
A19: 」と、お互いの顔を見つめ合ってしまいました | B19: 1 | C19: 1 | D19: 1 | E19: 1 | F19: -1 | G19: -10 | H19: -1 | I19: -10 | J19: -10
A20: ストーリーは確かにちょっとアレでしたが、初めて観た時の感動はかなりのものでした | B20: 4 | C20: 4 | D20: 5 | E20: 5 | F20: 1 | G20: -10 | H20: -1 | I20: -10 | J20: -10
A21: 当時映画館で見たときには度肝を抜かれた（古い表現だぁ）単純な娯楽作品なんだけど、遺伝子操作を行うことへの警鐘にも触れていて多面的に楽しめるお気軽作品 | B21: 5 | C21: 5 | D21: 5 | E21: 5 | F21: -1 | G21: -10 | H21: -1 | I21: -10 | J21: -10
A22: だから大人になった自分は、そんな子供心があった自分を今でも覚えていられるのはそのとき出会った映画のおかげなんですよね | B22: 4 | C22: 3 | D22: 4 | E22: 4 | F22: 1 | G22: -10 | H22: -1 | I22: -10 | J22: -10
A23: こうゆうのを「娯楽作品っ | B23: 1 | C23: 1 | D23: 1 | E23: 1 | F23: -1 | G23: -10 | H23: -1 | I23: -10 | J23: -10
A24: もっともストーリーはハラハラドキドキでちっとも安心できませんけどね | B24: 2 | C24: 4 | D24: 2 | E24: 1 | F24: 1 | G24: -10 | H24: -1 | I24: -10 | J24: -10
A25: 良くまとまった作品だと思います | B25: 4 | C25: 1 | D25: 1 | E25: 2 | F25: -1 | G25: -10 | H25: -1 | I25: -10 | J25: -10
A26: スピルバーグ最高 | B26: 4 | C26: 1 | D26: 2 | E26: 2 | F26: -1 | G26: -10 | H26: -1 | I26: -10 | J26: -10
A27: 観ててあのリアルな感じがストレートに伝わってきた | B27: 5 | C27: 4 | D27: 2 | E27: 3 | F27: -1 | G27: -10 | H27: -1 | I27: -10 | J27: -10
